Workbook

Sheet TOUR PUNTEN
A1: Vuelta Draft 👑 | D1: Roel | E1: Casper | F1: Jonas | G1: Dries
A3: Spelregels | C3: 1 | D3: Tadej Pogacar | E3: Jasper Philipsen | F3: Jonas Vingegaard | G3: Remco Evenepoel | H3: 29 min Wereldrecord
A4: Iedere speler kiest 10 unieke renners naar keuze (via een draft systeem). | C4: 2 | D4: Matteo Jorgenson | E4: Carlos Rodriguez | F4: Mads Pedersen | G4: Primoz Roglic
A5: Elke renner rijdt elke etappe mee. | C5: 3 | D5: Wout Van Aert | E5: Juan Ayuso | F5: Tom Pidcock | G5: Arnaud De Lie
A6: Nadien worden er volgens hetzelfde systeem nog 5 bank renners gekozen. | C6: 4 | D6: Pascal Ackermann | E6: Dylan Groenewegen | F6: Phil Bauhaus | G6: Lenny Martinez
C7: 5 | D7: Joao Almeida | E7: Bryan Coquard | F7: Aleksandr Vlasov | G7: Tobias Johannessen
A8: Algemene punten | C8: 6 | D8: Geraint Thomas | E8: Simon Yates | F8: Adam Yates | G8: Gerben Thijssen
C9: 7 | D9: Oier Lazkano | E9: Santiago Buitrago | F9: Biniam Girmay | G9: Romain Bardet
C10: 8 | D10: Mathieu Van Der Poel | E10: Fernando Gaviria | F10: Pello Bilbao | G10: Sam Bennett
C11: 9 | D11: Romain Gregoire | E11: Derek Gee | F11: Matej Mohoric | G11: Maxim Van Gils
C12: 10 | D12: Jai Hindley | E12: Felix Gall | F12: Alexander Kristoff | G12: Alberto Bettiol
C13: 11 | D13: Luca Mozzato | E13: Giulio Ciccone | F13: Ben Healy | G13: Stefan Kung
C14: 12 | D14: Marc Soler | E14: Mark Cavendish | F14: Soren Waerenskjold | G14: Michael Matthews
C15: 13 | D15: Warren Barguil | E15: David Gaudu | F15: Marijn Van Den Berg | G15: Mikel Landa
C16: 14 | D16: Christophe Laporte | E16: Oscar Onley | F16: Egan Bernal | G16: Richard Carapaz
C17: 15 | D17: Toms Skujins | E17: Wout Poels | F17: Alfred Wright | G17: Alexey Lutsenko
C18: 16 | D18: Tiesj Bennoot | E18: Enric Mas | F18: Wilco Kelderman | G18: Magnus Cort
C19: 17 | D19: Clement Champoussin | E19: Neilson Powless | F19: Louis Meintjes | G19: Fabio Jakobsen
C20: 18 | D20: Alex Aranburu | E20: Ilan Van Wilder | F20: Michal Kwiatkowski | G20: Danny Van Poppel
C21: 19
C22: 20
D26: Roel | E26: Casper | F26: Jonas | G26: Dries | H26: Team 5
C27: Rit 1 | D27: {=SUM(_xlfn.XLOOKUP(D$3:D$14,Puntentelling!$C$4:$C$32,Puntentelling!$F$4:$F$32,0,0,1))} -> 140 | E27: {=SUM(_xlfn.XLOOKUP(E$3:E$14,Puntentelling!$C$4:$C$32,Puntentelling!$F$4:$F$32,0,0,1))} -> 9 | F27: {=SUM(_xlfn.XLOOKUP(F$3:F$14,Puntentelling!$C$4:$C$32,Puntentelling!$F$4:$F$32,0,0,1))} -> 83 | G27: {=SUM(_xlfn.XLOOKUP(G$3:G$14,Puntentelling!$C$4:$C$32,Puntentelling!$F$4:$F$32,0,0,1))} -> 199
C28: Rit 2 | D28: {=SUM(_xlfn.XLOOKUP(D$3:D$14,Puntentelling!$I$4:$I$32,Puntentelling!$L$4:$L$32,0,0,1))} -> 34 | E28: {=SUM(_xlfn.XLOOKUP(E$3:E$14,Puntentelling!$I$4:$I$32,Puntentelling!$L$4:$L$32,0,0,1))} -> 32 | F28: {=SUM(_xlfn.XLOOKUP(F$3:F$14,Puntentelling!$I$4:$I$32,Puntentelling!$L$4:$L$32,0,0,1))} -> 13 | G28: {=SUM(_xlfn.XLOOKUP(G$3:G$14,Puntentelling!$I$4:$I$32,Puntentelling!$L$4:$L$32,0,0,1))} -> 36
C29: Rit 3 | D29: {=SUM(_xlfn.XLOOKUP(D$3:D$14,Puntentelling!$O$4:$O$32,Puntentelling!$R$4:$R$32,0,0,1))} -> 15 | E29: {=SUM(_xlfn.XLOOKUP(E$3:E$14,Puntentelling!$O$4:$O$32,Puntentelling!$R$4:$R$32,0,0,1))} -> 145 | F29: {=SUM(_xlfn.XLOOKUP(F$3:F$14,Puntentelling!$O$4:$O$32,Puntentelling!$R$4:$R$32,0,0,1))} -> 197 | G29: {=SUM(_xlfn.XLOOKUP(G$3:G$14,Puntentelling!$O$4:$O$32,Puntentelling!$R$4:$R$32,0,0,1))} -> 105
C30: Rit 4 | D30: {=SUM(_xlfn.XLOOKUP(D$3:D$14,Puntentelling!$U$4:$U$32,Puntentelling!$X$4:$X$32,0,0,1))} -> 162 | E30: {=SUM(_xlfn.XLOOKUP(E$3:E$14,Puntentelling!$U$4:$U$32,Puntentelling!$X$4:$X$32,0,0,1))} -> 161 | F30: {=SUM(_xlfn.XLOOKUP(F$3:F$14,Puntentelling!$U$4:$U$32,Puntentelling!$X$4:$X$32,0,0,1))} -> 70 | G30: {=SUM(_xlfn.XLOOKUP(G$3:G$14,Puntentelling!$U$4:$U$32,Puntentelling!$X$4:$X$32,0,0,1))} -> 145
C31: Rit 5 | D31: {=SUM(_xlfn.XLOOKUP(D$3:D$14,Puntentelling!$AA$4:$AA$32,Puntentelling!$AD$4:$AD$32,0,0,1))} -> 45 | E31: {=SUM(_xlfn.XLOOKUP(E$3:E$14,Puntentelling!$AA$4:$AA$32,Puntentelling!$AD$4:$AD$32,0,0,1))} -> 222 | F31: {=SUM(_xlfn.XLOOKUP(F$3:F$14,Puntentelling!$AA$4:$AA$32,Puntentelling!$AD$4:$AD$32,0,0,1))} -> 95 | G31: {=SUM(_xlfn.XLOOKUP(G$3:G$14,Puntentelling!$AA$4:$AA$32,Puntentelling!$AD$4:$AD$32,0,0,1))} -> 101
C32: Rit 6 | D32: {=SUM(_xlfn.XLOOKUP(D$3:D$14,Puntentelling!$AG$4:$AG$32,Puntentelling!$AJ$4:$AJ$32,0,0,1))} -> 75 | E32: {=SUM(_xlfn.XLOOKUP(E$3:E$14,Puntentelling!$AG$4:$AG$32,Puntentelling!$AJ$4:$AJ$32,0,0,1))} -> 187 | F32: {=SUM(_xlfn.XLOOKUP(F$3:F$14,Puntentelling!$AG$4:$AG$32,Puntentelling!$AJ$4:$AJ$32,0,0,1))} -> 184 | G32: {=SUM(_xlfn.XLOOKUP(G$3:G$14,Puntentelling!$AG$4:$AG$32,Puntentelling!$AJ$4:$AJ$32,0,0,1))} -> 70
C33: Rit 7 | D33: {=SUM(_xlfn.XLOOKUP(D$3:D$14,Puntentelling!$AM$4:$AM$32,Puntentelling!$AP$4:$AP$32,0,0,1))} -> 158 | E33: {=SUM(_xlfn.XLOOKUP(E$3:E$14,Puntentelling!$AM$4:$AM$32,Puntentelling!$AP$4:$AP$32,0,0,1))} -> 39 | F33: {=SUM(_xlfn.XLOOKUP(F$3:F$14,Puntentelling!$AM$4:$AM$32,Puntentelling!$AP$4:$AP$32,0,0,1))} -> 111 | G33: {=SUM(_xlfn.XLOOKUP(G$3:G$14,Puntentelling!$AM$4:$AM$32,Puntentelling!$AP$4:$AP$32,0,0,1))} -> 192
C34: Rit 8 | D34: {=SUM(_xlfn.XLOOKUP(D$3:D$14,Puntentelling!$AS$4:$AS$32,Puntentelling!$AV$4:$AV$32,0,0,1))} -> 78 | E34: {=SUM(_xlfn.XLOOKUP(E$3:E$14,Puntentelling!$AS$4:$AS$32,Puntentelling!$AV$4:$AV$32,0,0,1))} -> 88 | F34: {=SUM(_xlfn.XLOOKUP(F$3:F$15,Puntentelling!$AS$4:$AS$32,Puntentelling!$AV$4:$AV$32,0,0,1))} -> 171 | G34: {=SUM(_xlfn.XLOOKUP(G$3:G$14,Puntentelling!$AS$4:$AS$32,Puntentelling!$AV$4:$AV$32,0,0,1))} -> 102
C35: Rit 9 | D35: {=SUM(_xlfn.XLOOKUP(D$3:D$14,Puntentelling!$AY$4:$AY$32,Puntentelling!$BB$4:$BB$32,0,0,1))} -> 35 | E35: {=SUM(_xlfn.XLOOKUP(E$3:E$14,Puntentelling!$AY$4:$AY$32,Puntentelling!$BB$4:$BB$32,0,0,1))} -> 67 | F35: {=SUM(_xlfn.XLOOKUP(F$3:F$15,Puntentelling!$AY$4:$AY$32,Puntentelling!$BB$4:$BB$32,0,0,1))} -> 159 | G35: {=SUM(_xlfn.XLOOKUP(G$3:G$14,Puntentelling!$AY$4:$AY$32,Puntentelling!$BB$4:$BB$32,0,0,1))} -> 27
C36: Rit 10 | D36: {=SUM(_xlfn.XLOOKUP(D$3:D$14,Puntentelling!$BE$4:$BE$32,Puntentelling!$BH$4:$BH$32,0,0,1))} -> 141 | E36: {=SUM(_xlfn.XLOOKUP(E$3:E$14,Puntentelling!$BE$4:$BE$32,Puntentelling!$BH$4:$BH$32,0,0,1))} -> 186 | F36: {=SUM(_xlfn.XLOOKUP(F$3:F$16,Puntentelling!$BE$4:$BE$32,Puntentelling!$BH$4:$BH$32,0,0,1))} -> 140 | G36: {=SUM(_xlfn.XLOOKUP(G$3:G$14,Puntentelling!$BE$4:$BE$32,Puntentelling!$BH$4:$BH$32,0,0,1))} -> 54
C37: Rit 11 | D37: {=SUM(_xlfn.XLOOKUP(D$3:D$14,Puntentelling!$BK$4:$BK$32,Puntentelling!$BN$4:$BN$32,0,0,1))} -> 146 | E37: {=SUM(_xlfn.XLOOKUP(E$3:E$14,Puntentelling!$BK$4:$BK$32,Puntentelling!$BN$4:$BN$32,0,0,1))} -> 135 | F37: {=SUM(_xlfn.XLOOKUP(F$3:F$16,Puntentelling!$BK$4:$BK$32,Puntentelling!$BN$4:$BN$32,0,0,1))} -> 157 | G37: {=SUM(_xlfn.XLOOKUP(G$3:G$14,Puntentelling!$BK$4:$BK$32,Puntentelling!$BN$4:$BN$32,0,0,1))} -> 130
C38: Rit 12 | D38: {=SUM(_xlfn.XLOOKUP(D$3:D$14,Puntentelling!$BQ$4:$BQ$32,Puntentelling!$BT$4:$BT$32,0,0,1))} -> 174 | E38: {=SUM(_xlfn.XLOOKUP(E$3:E$14,Puntentelling!$BQ$4:$BQ$32,Puntentelling!$BT$4:$BT$32,0,0,1))} -> 114 | F38: {=SUM(_xlfn.XLOOKUP(F$3:F$16,Puntentelling!$BQ$4:$BQ$32,Puntentelling!$BT$4:$BT$32,0,0,1))} -> 190 | G38: {=SUM(_xlfn.XLOOKUP(G$3:G$14,Puntentelling!$BQ$4:$BQ$32,Puntentelling!$BT$4:$BT$32,0,0,1))} -> 69
C39: Rit 13 | D39: {=SUM(_xlfn.XLOOKUP(D$3:D$14,Puntentelling!$BW$4:$BW$32,Puntentelling!$BZ$4:$BZ$32,0,0,1))} -> 185 | E39: {=SUM(_xlfn.XLOOKUP(E$3:E$14,Puntentelling!$BW$4:$BW$32,Puntentelling!$BZ$4:$BZ$32,0,0,1))} -> 128 | F39: {=SUM(_xlfn.XLOOKUP(F$3:F$18,Puntentelling!$BW$4:$BW$32,Puntentelling!$BZ$4:$BZ$32,0,0,1))} -> 82 | G39: {=SUM(_xlfn.XLOOKUP(G$3:G$15,Puntentelling!$BW$4:$BW$32,Puntentelling!$BZ$4:$BZ$32,0,0,1))} -> 24
C40: Rit 14 | D40: {=SUM(_xlfn.XLOOKUP(D$3:D$14,Puntentelling!$CC$4:$CC$32,Puntentelling!$CF$4:$CF$32,0,0,1))} -> 154 | E40: {=SUM(_xlfn.XLOOKUP(E$3:E$15,Puntentelling!$CC$4:$CC$32,Puntentelling!$CF$4:$CF$32,0,0,1))} -> 190 | F40: {=SUM(_xlfn.XLOOKUP(F$3:F$19,Puntentelling!$CC$4:$CC$32,Puntentelling!$CF$4:$CF$32,0,0,1))} -> 148 | G40: {=SUM(_xlfn.XLOOKUP(G$3:G$15,Puntentelling!$CC$4:$CC$32,Puntentelling!$CF$4:$CF$32,0,0,1))} -> 93
C41: Rit 15 | D41: {=SUM(_xlfn.XLOOKUP(D$3:D$14,Puntentelling!$CI$4:$CI$32,Puntentelling!$CL$4:$CL$32,0,0,1))} -> 184 | E41: {=SUM(_xlfn.XLOOKUP(E$3:E$15,Puntentelling!$CI$4:$CI$32,Puntentelling!$CL$4:$CL$32,0,0,1))} -> 107 | F41: {=SUM(_xlfn.XLOOKUP(F$3:F$19,Puntentelling!$CI$4:$CI$32,Puntentelling!$CL$4:$CL$32,0,0,1))} -> 133 | G41: {=SUM(_xlfn.XLOOKUP(G$3:G$16,Puntentelling!$CI$4:$CI$32,Puntentelling!$CL$4:$CL$32,0,0,1))} -> 165
C42: Rit 16 | D42: {=SUM(_xlfn.XLOOKUP(D$3:D$14,Puntentelling!$CO$4:$CO$32,Puntentelling!$CR$4:$CR$32,0,0,1))} -> 114 | E42: {=SUM(_xlfn.XLOOKUP(E$3:E$15,Puntentelling!$CO$4:$CO$32,Puntentelling!$CR$4:$CR$32,0,0,1))} -> 158 | F42: {=SUM(_xlfn.XLOOKUP(F$3:F$19,Puntentelling!$CO$4:$CO$32,Puntentelling!$CR$4:$CR$32,0,0,1))} -> 180 | G42: {=SUM(_xlfn.XLOOKUP(G$3:G$18,Puntentelling!$CO$4:$CO$32,Puntentelling!$CR$4:$CR$32,0,0,1))} -> 65
C43: Rit 17 | D43: {=SUM(_xlfn.XLOOKUP(D$3:D$14,Puntentelling!$CU$4:$CU$32,Puntentelling!$CX$4:$CX$32,0,0,1))} -> 21 | E43: {=SUM(_xlfn.XLOOKUP(E$3:E$15,Puntentelling!$CU$4:$CU$32,Puntentelling!$CX$4:$CX$32,0,0,1))} -> 80 | F43: {=SUM(_xlfn.XLOOKUP(F$3:F$20,Puntentelling!$CU$4:$CU$32,Puntentelling!$CX$4:$CX$32,0,0,1))} -> 23 | G43: {=SUM(_xlfn.XLOOKUP(G$3:G$18,Puntentelling!$CU$4:$CU$32,Puntentelling!$CX$4:$CX$32,0,0,1))} -> 140
C44: Rit 18 | D44: {=SUM(_xlfn.XLOOKUP(D$3:D$14,Puntentelling!$DA$4:$DA$32,Puntentelling!$DD$4:$DD$32,0,0,1))} -> 110 | E44: {=SUM(_xlfn.XLOOKUP(E$3:E$16,Puntentelling!$DA$4:$DA$32,Puntentelling!$DD$4:$DD$32,0,0,1))} -> 0 | F44: {=SUM(_xlfn.XLOOKUP(F$3:F$20,Puntentelling!$DA$4:$DA$32,Puntentelling!$DD$4:$DD$32,0,0,1))} -> 77 | G44: {=SUM(_xlfn.XLOOKUP(G$3:G$20,Puntentelling!$DA$4:$DA$32,Puntentelling!$DD$4:$DD$32,0,0,1))} -> 35
...

Sheet Puntentelling
B1: Rit 1 | H1: Rit 2 | N1: Rit 3 | T1: Rit 4 | Z1: Rit 5 | AF1: Rit 6 | AL1: Rit 7 | AR1: Rit 8 | AX1: Rit 9 | BD1: Rit 10 | BJ1: Rit 11 | BP1: Rit 12 | BV1: Rit 13 | CB1: Rit 14 | CH1: Rit 15 | CN1: Rit 16 | CT1: Rit 17 | CZ1: Rit 18 | DF1: Rit 19 | DL1: Rit 20 | DR1: Rit 21
B3: Positie | C3: Naam | D3: Punten | E3: Truien | F3: Totaal | H3: Positie | I3: Naam | J3: Punten | K3: Truien | L3: Totaal | N3: Positie | O3: Naam | P3: Punten | Q3: Truien | R3: Totaal | T3: Positie | U3: Naam | V3: Punten | W3: Truien | X3: Totaal | Z3: Positie | AA3: Naam | AB3: Punten | AC3: Truien | AD3: Totaal | AF3: Positie | AG3: Naam | AH3: Punten | AI3: Truien | AJ3: Totaal | AL3: Positie | AM3: Naam | AN3: Punten | AO3: Truien | AP3: Totaal | AR3: Positie | AS3: Naam | AT3: Punten | AU3: Truien | AV3: Totaal | AX3: Positie | AY3: Naam | AZ3: Punten | BA3: Truien | BB3: Totaal | BD3: Positie | BE3: Naam | BF3: Punten | BG3: Truien | BH3: Totaal | BJ3: Positie | BK3: Naam | BL3: Punten | BM3: Truien | BN3: Totaal | BP3: Positie | BQ3: Naam | BR3: Punten | BS3: Truien | BT3: Totaal | BV3: Positie | BW3: Naam | BX3: Punten | BY3: Truien | BZ3: Totaal | CB3: Positie | CC3: Naam | CD3: Punten | CE3: Truien | CF3: Totaal | CH3: Positie | CI3: Naam | CJ3: Punten | CK3: Truien | CL3: Totaal | CN3: Positie | CO3: Naam | CP3: Punten | CQ3: Truien | CR3: Totaal | CT3: Positie | CU3: Naam | CV3: Punten | CW3: Truien | CX3: Totaal | CZ3: Positie | DA3: Naam | DB3: Punten | DC3: Truien | DD3: Totaal | DF3: Positie | DG3: Naam | DH3: Punten | DI3: Truien | DJ3: Totaal | DL3: Positie | DM3: Naam | DN3: Punten | DO3: Truien | DP3: Totaal | DR3: Positie | DS3: Naam | DT3: Punten | DU3: Truien | DV3: Totaal
B4: 1 | C4: Romain Bardet | D4: 100 | E4: 10 | F4: =SUM(D4:E4) -> 110 | H4: 1 | I4: Kevin Vauquelin | J4: 100 | K4: 0 | L4: =SUM(J4:K4) -> 100 | N4: 1 | O4: Biniam Girmay | P4: 100 | Q4: 0 | R4: =SUM(P4:Q4) -> 100 | T4: 1 | U4: Tadej Pogacar | V4: 100 | W4: 10 | X4: =SUM(V4:W4) -> 110 | Z4: 1 | AA4: Mark Cavendish | AB4: 100 | AC4: 0 | AD4: =SUM(AB4:AC4) -> 100 | AF4: 1 | AG4: Dylan Groenewegen | AH4: 100 | AI4: 0 | AJ4: =SUM(AH4:AI4) -> 100 | AL4: 1 | AM4: Remco Evenepoel | AN4: 100 | AO4: 10 | AP4: =SUM(AN4:AO4) -> 110 | AR4: 1 | AS4: Biniam Girmay | AT4: 100 | AU4: 10 | AV4: =SUM(AT4:AU4) -> 110 | AX4: 1 | AY4: Anthony Turgis | AZ4: 100 | BA4: 0 | BB4: =SUM(AZ4:BA4) -> 100 | BD4: 1 | BE4: Jasper Philipsen | BF4: 100 | BG4: 0 | BH4: =SUM(BF4:BG4) -> 100 | BJ4: 1 | BK4: Jonas Vingegaard | BL4: 100 | BM4: 0 | BN4: =SUM(BL4:BM4) -> 100 | BP4: 1 | BQ4: Biniam Girmay | BR4: 100 | BS4: 10 | BT4: =SUM(BR4:BS4) -> 110 | BV4: 1 | BW4: Jasper Philipsen | BX4: 100 | BY4: 0 | BZ4: =SUM(BX4:BY4) -> 100 | CB4: 1 | CC4: Tadej Pogacar | CD4: 100 | CE4: 20 | CF4: =SUM(CD4:CE4) -> 120 | CH4: 1 | CI4: Tadej Pogacar | CJ4: 100 | CK4: 20 | CL4: =SUM(CJ4:CK4) -> 120 | CN4: 1 | CO4: Jasper Philipsen | CP4: 100 | CQ4: 0 | CR4: =SUM(CP4:CQ4) -> 100 | CT4: 1 | CU4: Richard Carapaz | CV4: 100 | CW4: 0 | CX4: =SUM(CV4:CW4) -> 100 | CZ4: 1 | DA4: Victor Campenaerts | DB4: 100 | DC4: 0 | DD4: =SUM(DB4:DC4) -> 100 | DF4: 1 | DG4: Tadej Pogacar | DH4: 100 | DI4: 10 | DJ4: =SUM(DH4:DI4) -> 110 | DL4: 1 | DM4: Tadej Pogacar | DN4: 100 | DO4: 10 | DP4: =SUM(DN4:DO4) -> 110 | DR4: 1 | DS4: Tadej Pogacar | DT4: 100 | DU4: 10 | DV4: =SUM(DT4:DU4) -> 110
B5: 2 | C5: Frank Van Den Broek | D5: 80 | E5: 20 | F5: =SUM(D5:E5) -> 100 | H5: 2 | I5: Jonas Abrahamsen | J5: 80 | K5: 20 | L5: =SUM(J5:K5) -> 100 | N5: 2 | O5: Fernando Gaviria | P5: 80 | Q5: 0 | R5: =SUM(P5:Q5) -> 80 | T5: 2 | U5: Remco Evenepoel | V5: 80 | W5: 10 | X5: =SUM(V5:W5) -> 90 | Z5: 2 | AA5: Jasper Philipsen | AB5: 80 | AC5: 0 | AD5: =SUM(AB5:AC5) -> 80 | AF5: 2 | AG5: Biniam Girmay | AH5: 80 | AI5: 10 | AJ5: =SUM(AH5:AI5) -> 90 | AL5: 2 | AM5: Tadej Pogacar | AN5: 80 | AO5: 10 | AP5: =SUM(AN5:AO5) -> 90 | AR5: 2 | AS5: Jasper Philipsen | AT5: 80 | AU5: 0 | AV5: =SUM(AT5:AU5) -> 80 | AX5: 2 | AY5: Tom Pidcock | AZ5: 80 | BA5: 0 | BB5: =SUM(AZ5:BA5) -> 80 | BD5: 2 | BE5: Biniam Girmay | BF5: 80 | BG5: 10 | BH5: =SUM(BF5:BG5) -> 90 | BJ5: 2 | BK5: Tadej Pogacar | BL5: 80 | BM5: 20 | BN5: =SUM(BL5:BM5) -> 100 | BP5: 2 | BQ5: Wout Van Aert | BR5: 80 | BS5: 0 | BT5: =SUM(BR5:BS5) -> 80 | BV5: 2 | BW5: Wout Van Aert | BX5: 80 | BY5: 0 | BZ5: =SUM(BX5:BY5) -> 80 | CB5: 2 | CC5: Jonas Vingegaard | CD5: 80 | CE5: 0 | CF5: =SUM(CD5:CE5) -> 80 | CH5: 2 | CI5: Jonas Vingegaard | CJ5: 80 | CK5: 0 | CL5: =SUM(CJ5:CK5) -> 80 | CN5: 2 | CO5: Phil Bauhaus | CP5: 80 | CQ5: 0 | CR5: =SUM(CP5:CQ5) -> 80 | CT5: 2 | CU5: Simon Yates | CV5: 80 | CW5: 0 | CX5: =SUM(CV5:CW5) -> 80 | CZ5: 2 | DA5: Matteo Vercher | DB5: 80 | DC5: 0 | DD5: =SUM(DB5:DC5) -> 80 | DF5: 2 | DG5: Matteo Jorgenson | DH5: 80 | DI5: 0 | DJ5: =SUM(DH5:DI5) -> 80 | DL5: 2 | DM5: Jonas Vingegaard | DN5: 80 | DO5: 0 | DP5: =SUM(DN5:DO5) -> 80 | DR5: 2 | DS5: Jonas Vingegaard | DT5: 80 | DU5: 0 | DV5: =SUM(DT5:DU5) -> 80
B6: 3 | C6: Wout Van Aert | D6: 65 | E6: 0 | F6: =SUM(D6:E6) -> 65 | H6: 3 | I6: Quentin Pacher | J6: 65 | K6: 0 | L6: =SUM(J6:K6) -> 65 | N6: 3 | O6: Arnaud De Lie | P6: 65 | Q6: 0 | R6: =SUM(P6:Q6) -> 65 | T6: 3 | U6: Juan Ayuso | V6: 65 | W6: 0 | X6: =SUM(V6:W6) -> 65 | Z6: 3 | AA6: Alexander Kristoff | AB6: 65 | AC6: 0 | AD6: =SUM(AB6:AC6) -> 65 | AF6: 3 | AG6: Fernando Gaviria | AH6: 65 | AI6: 0 | AJ6: =SUM(AH6:AI6) -> 65 | AL6: 3 | AM6: Primoz Roglic | AN6: 65 | AO6: 0 | AP6: =SUM(AN6:AO6) -> 65 | AR6: 3 | AS6: Arnaud De Lie | AT6: 65 | AU6: 0 | AV6: =SUM(AT6:AU6) -> 65 | AX6: 3 | AY6: Derek Gee | AZ6: 65 | BA6: 0 | BB6: =SUM(AZ6:BA6) -> 65 | BD6: 3 | BE6: Pascal Ackermann | BF6: 65 | BG6: 0 | BH6: =SUM(BF6:BG6) -> 65 | BJ6: 3 | BK6: Remco Evenepoel | BL6: 65 | BM6: 10 | BN6: =SUM(BL6:BM6) -> 75 | BP6: 3 | BQ6: Pascal Ackermann | BR6: 65 | BS6: 0 | BT6: =SUM(BR6:BS6) -> 65 | BV6: 3 | BW6: Pascal Ackermann | BX6: 65 | BY6: 0 | BZ6: =SUM(BX6:BY6) -> 65 | CB6: 3 | CC6: Remco Evenepoel | CD6: 65 | CE6: 10 | CF6: =SUM(CD6:CE6) -> 75 | CH6: 3 | CI6: Remco Evenepoel | CJ6: 65 | CK6: 10 | CL6: =SUM(CJ6:CK6) -> 75 | CN6: 3 | CO6: Alexander Kristoff | CP6: 65 | CQ6: 0 | CR6: =SUM(CP6:CQ6) -> 65 | CT6: 3 | CU6: Enric Mas | CV6: 65 | CW6: 0 | CX6: =SUM(CV6:CW6) -> 65 | CZ6: 3 | DA6: Michal Kwiatkowski | DB6: 65 | DC6: 0 | DD6: =SUM(DB6:DC6) -> 65 | DF6: 3 | DG6: Simon Yates | DH6: 65 | DI6: 0 | DJ6: =SUM(DH6:DI6) -> 65 | DL6: 3 | DM6: Richard Carapaz | DN6: 65 | DO6: 10 | DP6: =SUM(DN6:DO6) -> 75 | DR6: 3 | DS6: Remco Evenepoel | DT6: 65 | DU6: 10 | DV6: =SUM(DT6:DU6) -> 75
B7: 4 | C7: Tadej Pogacar | D7: 55 | E7: 0 | F7: =SUM(D7:E7) -> 55 | H7: 4 | I7: Cristian Rodriguez | J7: 55 | K7: 0 | L7: =SUM(J7:K7) -> 55 | N7: 4 | O7: Mads Pedersen | P7: 55 | Q7: 0 | R7: =SUM(P7:Q7) -> 55 | T7: 4 | U7: Primoz Roglic | V7: 55 | W7: 0 | X7: =SUM(V7:W7) -> 55 | Z7: 4 | AA7: Arnaud De Lie | AB7: 55 | AC7: 0 | AD7: =SUM(AB7:AC7) -> 55 | AF7: 4 | AG7: Phil Bauhaus | AH7: 55 | AI7: 0 | AJ7: =SUM(AH7:AI7) -> 55 | AL7: 4 | AM7: Jonas Vingegaard | AN7: 55 | AO7: 0 | AP7: =SUM(AN7:AO7) -> 55 | AR7: 4 | AS7: Pascal Ackermann | AT7: 55 | AU7: 0 | AV7: =SUM(AT7:AU7) -> 55 | AX7: 4 | AY7: Alex Aranburu | AZ7: 55 | BA7: 0 | BB7: =SUM(AZ7:BA7) -> 55 | BD7: 4 | BE7: Wout Van Aert | BF7: 55 | BG7: 0 | BH7: =SUM(BF7:BG7) -> 55 | BJ7: 4 | BK7: Primoz Roglic | BL7: 55 | BM7: 0 | BN7: =SUM(BL7:BM7) -> 55 | BP7: 4 | BQ7: Jasper Philipsen | BR7: 55 | BS7: 0 | BT7: =SUM(BR7:BS7) -> 55 | BV7: 4 | BW7: Biniam Girmay | BX7: 55 | BY7: 10 | BZ7: =SUM(BX7:BY7) -> 65 | CB7: 4 | CC7: Carlos Rodriguez | CD7: 55 | CE7: 0 | CF7: =SUM(CD7:CE7) -> 55 | CH7: 4 | CI7: Mikel Landa | CJ7: 55 | CK7: 0 | CL7: =SUM(CJ7:CK7) -> 55 | CN7: 4 | CO7: Sam Bennett | CP7: 55 | CQ7: 0 | CR7: =SUM(CP7:CQ7) -> 55 | CT7: 4 | CU7: Laurens De Plus | CV7: 55 | CW7: 0 | CX7: =SUM(CV7:CW7) -> 55 | CZ7: 4 | DA7: Toms Skujins | DB7: 55 | DC7: 0 | DD7: =SUM(DB7:DC7) -> 55 | DF7: 4 | DG7: Richard Carapaz | DH7: 55 | DI7: 10 | DJ7: =SUM(DH7:DI7) -> 65 | DL7: 4 | DM7: Remco Evenepoel | DN7: 55 | DO7: 10 | DP7: =SUM(DN7:DO7) -> 65 | DR7: 4 | DS7: Matteo Jorgenson | DT7: 55 | DU7: 0 | DV7: =SUM(DT7:DU7) -> 55
B8: 5 | C8: Maxim Van Gils | D8: 45 | E8: 0 | F8: =SUM(D8:E8) -> 45 | H8: 5 | I8: Harold Tejada | J8: 45 | K8: 0 | L8: =SUM(J8:K8) -> 45 | N8: 5 | O8: Dylan Groenewegen | P8: 45 | Q8: 0 | R8: =SUM(P8:Q8) -> 45 | T8: 5 | U8: Jonas Vingegaard | V8: 45 | W8: 0 | X8: =SUM(V8:W8) -> 45 | Z8: 5 | AA8: Fabio Jakobsen | AB8: 45 | AC8: 0 | AD8: =SUM(AB8:AC8) -> 45 | AF8: 5 | AG8: Arnaud De Lie | AH8: 45 | AI8: 0 | AJ8: =SUM(AH8:AI8) -> 45 | AL8: 5 | AM8: Victor Campenaerts | AN8: 45 | AO8: 0 | AP8: =SUM(AN8:AO8) -> 45 | AR8: 5 | AS8: Marijn Van Den Berg | AT8: 45 | AU8: 0 | AV8: =SUM(AT8:AU8) -> 45 | AX8: 5 | AY8: Ben Healy | AZ8: 45 | BA8: 0 | BB8: =SUM(AZ8:BA8) -> 45 | BD8: 5 | BE8: Fernando Gaviria | BF8: 45 | BG8: 0 | BH8: =SUM(BF8:BG8) -> 45 | BJ8: 5 | BK8: Giulio Ciccone | BL8: 45 | BM8: 0 | BN8: =SUM(BL8:BM8) -> 45 | BP8: 5 | BQ8: Arnaud De Lie | BR8: 45 | BS8: 0 | BT8: =SUM(BR8:BS8) -> 45 | BV8: 5 | BW8: Nikias Arndt | BX8: 45 | BY8: 0 | BZ8: =SUM(BX8:BY8) -> 45 | CB8: 5 | CC8: Giulio Ciccone | CD8: 45 | CE8: 0 | CF8: =SUM(CD8:CE8) -> 45 | CH8: 5 | CI8: Joao Almeida | CJ8: 45 | CK8: 0 | CL8: =SUM(CJ8:CK8) -> 45 | CN8: 5 | CO8: Wout Van Aert | CP8: 45 | CQ8: 0 | CR8: =SUM(CP8:CQ8) -> 45 | CT8: 5 | CU8: Oscar Onley | CV8: 45 | CW8: 0 | CX8: =SUM(CV8:CW8) -> 45 | CZ8: 5 | DA8: Oier Lazkano | DB8: 45 | DC8: 0 | DD8: =SUM(DB8:DC8) -> 45 | DF8: 5 | DG8: Remco Evenepoel | DH8: 45 | DI8: 10 | DJ8: =SUM(DH8:DI8) -> 55 | DL8: 5 | DM8: Enric Mas | DN8: 45 | DO8: 0 | DP8: =SUM(DN8:DO8) -> 45 | DR8: 5 | DS8: Joao Almeida | DT8: 45 | DU8: 0 | DV8: =SUM(DT8:DU8) -> 45
B9: 6 | C9: Alex Aranburu | D9: 35 | E9: 0 | F9: =SUM(D9:E9) -> 35 | H9: 6 | I9: Nelson Oliveira | J9: 35 | K9: 0 | L9: =SUM(J9:K9) -> 35 | N9: 6 | O9: Phil Bauhaus | P9: 35 | Q9: 0 | R9: =SUM(P9:Q9) -> 35 | T9: 6 | U9: Carlos Rodriguez | V9: 35 | W9: 0 | X9: =SUM(V9:W9) -> 35 | Z9: 6 | AA9: Pascal Ackermann | AB9: 35 | AC9: 0 | AD9: =SUM(AB9:AC9) -> 35 | AF9: 6 | AG9: Wout Van Aert | AH9: 35 | AI9: 0 | AJ9: =SUM(AH9:AI9) -> 35 | AL9: 6 | AM9: Kevin Vauquelin | AN9: 35 | AO9: 0 | AP9: =SUM(AN9:AO9) -> 35 | AR9: 6 | AS9: Ryan Gibbons | AT9: 35 | AU9: 0 | AV9: =SUM(AT9:AU9) -> 35 | AX9: 6 | AY9: Alexey Lutsenko | AZ9: 35 | BA9: 0 | BB9: =SUM(AZ9:BA9) -> 35 | BD9: 6 | BE9: Sam Bennett | BF9: 35 | BG9: 0 | BH9: =SUM(BF9:BG9) -> 35 | BJ9: 6 | BK9: Joao Almeida | BL9: 35 | BM9: 0 | BN9: =SUM(BL9:BM9) -> 35 | BP9: 6 | BQ9: Alexander Kristoff | BR9: 35 | BS9: 0 | BT9: =SUM(BR9:BS9) -> 35 | BV9: 6 | BW9: Jasper Stuyven | BX9: 35 | BY9: 0 | BZ9: =SUM(BX9:BY9) -> 35 | CB9: 6 | CC9: Santiago Buitrago | CD9: 35 | CE9: 0 | CF9: =SUM(CD9:CE9) -> 35 | CH9: 6 | CI9: Adam Yates | CJ9: 35 | CK9: 0 | CL9: =SUM(CJ9:CK9) -> 35 | CN9: 6 | CO9: Pascal Ackermann | CP9: 35 | CQ9: 0 | CR9: =SUM(CP9:CQ9) -> 35 | CT9: 6 | CU9: Guillaume Martin | CV9: 35 | CW9: 0 | CX9: =SUM(CV9:CW9) -> 35 | CZ9: 6 | DA9: Bart Lemmen | DB9: 35 | DC9: 0 | DD9: =SUM(DB9:DC9) -> 35 | DF9: 6 | DG9: Jonas Vingegaard | DH9: 35 | DI9: 0 | DJ9: =SUM(DH9:DI9) -> 35 | DL9: 6 | DM9: Joao Almeida | DN9: 35 | DO9: 0 | DP9: =SUM(DN9:DO9) -> 35 | DR9: 6 | DS9: Derek Gee | DT9: 35 | DU9: 0 | DV9: =SUM(DT9:DU9) -> 35
B10: 7 | C10: Mads Pedersen | D10: 30 | E10: 0 | F10: =SUM(D10:E10) -> 30 | H10: 7 | I10: Axel Laurance | J10: 30 | K10: 5 | L10: =SUM(J10:K10) -> 35 | N10: 7 | O10: Fabio Jakobsen | P10: 30 | Q10: 0 | R10: =SUM(P10:Q10) -> 30 | T10: 7 | U10: Mikel Landa | V10: 30 | W10: 0 | X10: =SUM(V10:W10) -> 30 | Z10: 7 | AA10: Arnaud Demare | AB10: 30 | AC10: 0 | AD10: =SUM(AB10:AC10) -> 30 | AF10: 7 | AG10: Arnaud Demare | AH10: 30 | AI10: 0 | AJ10: =SUM(AH10:AI10) -> 30 | AL10: 7 | AM10: Matteo Jorgenson | AN10: 30 | AO10: 0 | AP10: =SUM(AN10:AO10) -> 30 | AR10: 7 | AS10: Anthony Turgis | AT10: 30 | AU10: 0 | AV10: =SUM(AT10:AU10) -> 30 | AX10: 7 | AY10: Javier Romo | AZ10: 30 | BA10: 0 | BB10: =SUM(AZ10:BA10) -> 30 | BD10: 7 | BE10: John Degenkolb | BF10: 30 | BG10: 0 | BH10: =SUM(BF10:BG10) -> 30 | BJ10: 7 | BK10: Adam Yates | BL10: 30 | BM10: 0 | BN10: =SUM(BL10:BM10) -> 30 | BP10: 7 | BQ10: Phil Bauhaus | BR10: 30 | BS10: 0 | BT10: =SUM(BR10:BS10) -> 30 | BV10: 7 | BW10: Clement Russo | BX10: 30 | BY10: 0 | BZ10: =SUM(BX10:BY10) -> 30 | CB10: 7 | CC10: Adam Yates | CD10: 30 | CE10: 0 | CF10: =SUM(CD10:CE10) -> 30 | CH10: 7 | CI10: Santiago Buitrago | CJ10: 30 | CK10: 0 | CL10: =SUM(CJ10:CK10) -> 30 | CN10: 7 | CO10: Bryan Coquard | CP10: 30 | CQ10: 0 | CR10: =SUM(CP10:CQ10) -> 30 | CT10: 7 | CU10: Magnus Cort | CV10: 30 | CW10: 0 | CX10: =SUM(CV10:CW10) -> 30 | CZ10: 7 | DA10: Krists Neilands | DB10: 30 | DC10: 0 | DD10: =SUM(DB10:DC10) -> 30 | DF10: 7 | DG10: Joao Almeida | DH10: 30 | DI10: 0 | DJ10: =SUM(DH10:DI10) -> 30 | DL10: 7 | DM10: Matteo Jorgenson | DN10: 30 | DO10: 0 | DP10: =SUM(DN10:DO10) -> 30 | DR10: 7 | DS10: Mikel Landa | DT10: 30 | DU10: 0 | DV10: =SUM(DT10:DU10) -> 30
B11: 8 | C11: Remco Evenepoel | D11: 25 | E11: 0 | F11: =SUM(D11:E11) -> 25 | H11: 8 | I11: Mike Teunissen | J11: 25 | K11: 0 | L11: =SUM(J11:K11) -> 25 | N11: 8 | O11: Davide Ballerini | P11: 25 | Q11: 0 | R11: =SUM(P11:Q11) -> 25 | T11: 8 | U11: Joao Almeida | V11: 25 | W11: 0 | X11: =SUM(V11:W11) -> 25 | Z11: 8 | AA11: Gerben Thijssen | AB11: 25 | AC11: 0 | AD11: =SUM(AB11:AC11) -> 25 | AF11: 8 | AG11: Alexander Kristoff | AH11: 25 | AI11: 0 | AJ11: =SUM(AH11:AI11) -> 25 | AL11: 8 | AM11: Joao Almeida | AN11: 25 | AO11: 0 | AP11: =SUM(AN11:AO11) -> 25 | AR11: 8 | AS11: Alfred Wright | AT11: 25 | AU11: 0 | AV11: =SUM(AT11:AU11) -> 25 | AX11: 8 | AY11: Jasper Stuyven | AZ11: 25 | BA11: 0 | BB11: =SUM(AZ11:BA11) -> 25 | BD11: 8 | BE11: Phil Bauhaus | BF11: 25 | BG11: 0 | BH11: =SUM(BF11:BG11) -> 25 | BJ11: 8 | BK11: Mikel Landa | BL11: 25 | BM11: 0 | BN11: =SUM(BL11:BM11) -> 25 | BP11: 8 | BQ11: Bryan Coquard | BR11: 25 | BS11: 0 | BT11: =SUM(BR11:BS11) -> 25 | BV11: 8 | BW11: Bryan Coquard | BX11: 25 | BY11: 0 | BZ11: =SUM(BX11:BY11) -> 25 | CB11: 8 | CC11: Felix Gall | CD11: 25 | CE11: 0 | CF11: =SUM(CD11:CE11) -> 25 | CH11: 8 | CI11: Carlos Rodriguez | CJ11: 25 | CK11: 0 | CL11: =SUM(CJ11:CK11) -> 25 | CN11: 8 | CO11: Soren Waerenskjold | CP11: 25 | CQ11: 0 | CR11: =SUM(CP11:CQ11) -> 25 | CT11: 8 | CU11: Wout Poels | CV11: 25 | CW11: 0 | CX11: =SUM(CV11:CW11) -> 25 | CZ11: 8 | DA11: Jai Hindley | DB11: 25 | DC11: 0 | DD11: =SUM(DB11:DC11) -> 25 | DF11: 8 | DG11: Mikel Landa | DH11: 25 | DI11: 0 | DJ11: =SUM(DH11:DI11) -> 25 | DL11: 8 | DM11: Mikel Landa | DN11: 25 | DO11: 0 | DP11: =SUM(DN11:DO11) -> 25 | DR11: 8 | DS11: Harold Tejada | DT11: 25 | DU11: 0 | DV11: =SUM(DT11:DU11) -> 25
B12: 9 | C12: Pello Bilbao | D12: 20 | E12: 0 | F12: =SUM(D12:E12) -> 20 | H12: 9 | I12: Hugo Houle | J12: 20 | K12: 0 | L12: =SUM(J12:K12) -> 20 | N12: 9 | O12: Sam Bennett | P12: 20 | Q12: 0 | R12: =SUM(P12:Q12) -> 20 | T12: 9 | U12: Giulio Ciccone | V12: 20 | W12: 0 | X12: =SUM(V12:W12) -> 20 | Z12: 9 | AA12: Biniam Girmay | AB12: 20 | AC12: 10 | AD12: =SUM(AB12:AC12) -> 30 | AF12: 9 | AG12: Pascal Ackermann | AH12: 20 | AI12: 0 | AJ12: =SUM(AH12:AI12) -> 20 | AL12: 9 | AM12: Ben Healy | AN12: 20 | AO12: 0 | AP12: =SUM(AN12:AO12) -> 20 | AR12: 9 | AS12: Alex Aranburu | AT12: 20 | AU12: 0 | AV12: =SUM(AT12:AU12) -> 20 | AX12: 9 | AY12: Biniam Girmay | AZ12: 20 | BA12: 10 | BB12: =SUM(AZ12:BA12) -> 30 | BD12: 9 | BE12: Dylan Groenewegen | BF12: 20 | BG12: 0 | BH12: =SUM(BF12:BG12) -> 20 | BJ12: 9 | BK12: Carlos Rodriguez | BL12: 20 | BM12: 0 | BN12: =SUM(BL12:BM12) -> 20 | BP12: 9 | BQ12: Dylan Groenewegen | BR12: 20 | BS12: 0 | BT12: =SUM(BR12:BS12) -> 20 | BV12: 9 | BW12: Tadej Pogacar | BX12: 20 | BY12: 20 | BZ12: =SUM(BX12:BY12) -> 40 | CB12: 9 | CC12: Matteo Jorgenson | CD12: 20 | CE12: 0 | CF12: =SUM(CD12:CE12) -> 20 | CH12: 9 | CI12: Richard Carapaz | CJ12: 20 | CK12: 0 | CL12: =SUM(CJ12:CK12) -> 20 | CN12: 9 | CO12: Ryan Gibbons | CP12: 20 | CQ12: 0 | CR12: =SUM(CP12:CQ12) -> 20 | CT12: 9 | CU12: Jordan Jegat | CV12: 20 | CW12: 0 | CX12: =SUM(CV12:CW12) -> 20 | CZ12: 9 | DA12: Wout Van Aert | DB12: 20 | DC12: 0 | DD12: =SUM(DB12:DC12) -> 20 | DF12: 9 | DG12: Wilco Kelderman | DH12: 20 | DI12: 0 | DJ12: =SUM(DH12:DI12) -> 20 | DL12: 9 | DM12: Adam Yates | DN12: 20 | DO12: 0 | DP12: =SUM(DN12:DO12) -> 20 | DR12: 9 | DS12: Santiago Buitrago | DT12: 20 | DU12: 0 | DV12: =SUM(DT12:DU12) -> 20
B13: 10 | C13: Alberto Bettiol | D13: 17 | E13: 0 | F13: =SUM(D13:E13) -> 17 | H13: 10 | I13: Richard Carapaz | J13: 17 | K13: 0 | L13: =SUM(J13:K13) -> 17 | N13: 10 | O13: Bryan Coquard | P13: 17 | Q13: 0 | R13: =SUM(P13:Q13) -> 17 | T13: 10 | U13: Santiago Buitrago | V13: 17 | W13: 0 | X13: =SUM(V13:W13) -> 17 | Z13: 10 | AA13: Marijn Van Den Berg | AB13: 17 | AC13: 0 | AD13: =SUM(AB13:AC13) -> 17 | AF13: 10 | AG13: Piet Allegaert | AH13: 17 | AI13: 0 | AJ13: =SUM(AH13:AI13) -> 17 | AL13: 10 | AM13: Stefan Kung | AN13: 17 | AO13: 0 | AP13: =SUM(AN13:AO13) -> 17 | AR13: 10 | AS13: Remco Evenepoel | AT13: 17 | AU13: 10 | AV13: =SUM(AT13:AU13) -> 27 | AX13: 10 | AY13: Michael Matthews | AZ13: 17 | BA13: 0 | BB13: =SUM(AZ13:BA13) -> 17 | BD13: 10 | BE13: Axel Zingle | BF13: 17 | BG13: 0 | BH13: =SUM(BF13:BG13) -> 17 | BJ13: 10 | BK13: Felix Gall | BL13: 17 | BM13: 0 | BN13: =SUM(BL13:BM13) -> 17 | BP13: 10 | BQ13: Ryan Gibbons | BR13: 17 | BS13: 0 | BT13: =SUM(BR13:BS13) -> 17 | BV13: 10 | BW13: Soren Waerenskjold | BX13: 17 | BY13: 0 | BZ13: =SUM(BX13:BY13) -> 17 | CB13: 10 | CC13: Derek Gee | CD13: 17 | CE13: 0 | CF13: =SUM(CD13:CE13) -> 17 | CH13: 10 | CI13: Felix Gall | CJ13: 17 | CK13: 0 | CL13: =SUM(CJ13:CK13) -> 17 | CN13: 10 | CO13: Danny Van Poppel | CP13: 17 | CQ13: 0 | CR13: =SUM(CP13:CQ13) -> 17 | CT13: 10 | CU13: Alex Aranburu | CV13: 17 | CW13: 0 | CX13: =SUM(CV13:CW13) -> 17 | CZ13: 10 | DA13: Michael Matthews | DB13: 17 | DC13: 0 | DD13: =SUM(DB13:DC13) -> 17 | DF13: 10 | DG13: Derek Gee | DH13: 17 | DI13: 0 | DJ13: =SUM(DH13:DI13) -> 17 | DL13: 10 | DM13: Romain Bardet | DN13: 17 | DO13: 0 | DP13: =SUM(DN13:DO13) -> 17 | DR13: 10 | DS13: Adam Yates | DT13: 17 | DU13: 0 | DV13: =SUM(DT13:DU13) -> 17
B14: 11 | C14: Tom Pidcock | D14: 15 | E14: 0 | F14: =SUM(D14:E14) -> 15 | H14: 11 | I14: Jordan Jegat | J14: 15 | K14: 0 | L14: =SUM(J14:K14) -> 15 | N14: 11 | O14: Jonas Rickaert | P14: 15 | Q14: 0 | R14: =SUM(P14:Q14) -> 15 | T14: 11 | U14: Felix Gall | V14: 15 | W14: 0 | X14: =SUM(V14:W14) -> 15 | Z14: 11 | AA14: Fernando Gaviria | AB14: 15 | AC14: 0 | AD14: =SUM(AB14:AC14) -> 15 | AF14: 11 | AG14: Bryan Coquard | AH14: 15 | AI14: 0 | AJ14: =SUM(AH14:AI14) -> 15 | AL14: 11 | AM14: Aleksandr Vlasov | AN14: 15 | AO14: 0 | AP14: =SUM(AN14:AO14) -> 15 | AR14: 11 | AS14: Soren Kragh Andersen | AT14: 15 | AU14: 0 | AV14: =SUM(AT14:AU14) -> 15 | AX14: 11 | AY14: Mathieu Van Der Poel | AZ14: 15 | BA14: 0 | BB14: =SUM(AZ14:BA14) -> 15 | BD14: 11 | BE14: Marijn Van Den Berg | BF14: 15 | BG14: 0 | BH14: =SUM(BF14:BG14) -> 15 | BJ14: 11 | BK14: Santiago Buitrago | BL14: 15 | BM14: 0 | BN14: =SUM(BL14:BM14) -> 15 | BP14: 11 | BQ14: Marijn Van Den Berg | BR14: 15 | BS14: 0 | BT14: =SUM(BR14:BS14) -> 15 | BV14: 11 | BW14: Luka Mezgec | BX14: 15 | BY14: 0 | BZ14: =SUM(BX14:BY14) -> 15 | CB14: 11 | CC14: Mikel Landa | CD14: 15 | CE14: 0 | CF14: =SUM(CD14:CE14) -> 15 | CH14: 11 | CI14: Tobias Johannessen | CJ14: 15 | CK14: 0 | CL14: =SUM(CJ14:CK14) -> 15 | CN14: 11 | CO14: Stefan Bissegger | CP14: 15 | CQ14: 0 | CR14: =SUM(CP14:CQ14) -> 15 | CT14: 11 | CU14: Toms Skujins | CV14: 15 | CW14: 0 | CX14: =SUM(CV14:CW14) -> 15 | CZ14: 11 | DA14: Dorian Godon | DB14: 15 | DC14: 0 | DD14: =SUM(DB14:DC14) -> 15 | DF14: 11 | DG14: Adam Yates | DH14: 15 | DI14: 0 | DJ14: =SUM(DH14:DI14) -> 15 | DL14: 11 | DM14: Tobias Johannessen | DN14: 15 | DO14: 0 | DP14: =SUM(DN14:DO14) -> 15 | DR14: 11 | DS14: Lenny Martinez | DT14: 15 | DU14: 0 | DV14: =SUM(DT14:DU14) -> 15
B15: 12 | C15: Egan Bernal | D15: 14 | E15: 0 | F15: =SUM(D15:E15) -> 14 | H15: 12 | I15: Remco Evenepoel | J15: 14 | K15: 10 | L15: =SUM(J15:K15) -> 24 | N15: 12 | O15: Anthony Turgis | P15: 14 | Q15: 0 | R15: =SUM(P15:Q15) -> 14 | T15: 12 | U15: Matteo Jorgenson | V15: 14 | W15: 0 | X15: =SUM(V15:W15) -> 14 | Z15: 12 | AA15: Dylan Groenewegen | AB15: 14 | AC15: 0 | AD15: =SUM(AB15:AC15) -> 14 | AF15: 12 | AG15: Sandy Dujardin | AH15: 14 | AI15: 0 | AJ15: =SUM(AH15:AI15) -> 14 | AL15: 12 | AM15: Stefan Bissegger | AN15: 14 | AO15: 0 | AP15: =SUM(AN15:AO15) -> 14 | AR15: 12 | AS15: Alexander Kristoff | AT15: 14 | AU15: 0 | AV15: =SUM(AT15:AU15) -> 14 | AX15: 12 | AY15: Rasmus Tiller | AZ15: 14 | BA15: 0 | BB15: =SUM(AZ15:BA15) -> 14 | BD15: 12 | BE15: Oliver Naessen | BF15: 14 | BG15: 0 | BH15: =SUM(BF15:BG15) -> 14 | BJ15: 12 | BK15: Derek Gee | BL15: 14 | BM15: 0 | BN15: =SUM(BL15:BM15) -> 14 | BP15: 12 | BQ15: Sam Bennett | BR15: 14 | BS15: 0 | BT15: =SUM(BR15:BS15) -> 14 | BV15: 12 | BW15: Maxim Van Gils | BX15: 14 | BY15: 0 | BZ15: =SUM(BX15:BY15) -> 14 | CB15: 12 | CC15: Joao Almeida | CD15: 14 | CE15: 0 | CF15: =SUM(CD15:CE15) -> 14 | CH15: 12 | CI15: Derek Gee | CJ15: 14 | CK15: 0 | CL15: =SUM(CJ15:CK15) -> 14 | CN15: 12 | CO15: Mathieu Van Der Poel | CP15: 14 | CQ15: 0 | CR15: =SUM(CP15:CQ15) -> 14 | CT15: 12 | CU15: Stephen Williams | CV15: 14 | CW15: 0 | CX15: =SUM(CV15:CW15) -> 14 | CZ15: 12 | DA15: Quentin Pacher | DB15: 14 | DC15: 0 | DD15: =SUM(DB15:DC15) -> 14 | DF15: 12 | DG15: Enric Mas | DH15: 14 | DI15: 0 | DJ15: =SUM(DH15:DI15) -> 14 | DL15: 12 | DM15: Derek Gee | DN15: 14 | DO15: 0 | DP15: =SUM(DN15:DO15) -> 14 | DR15: 12 | DS15: Simon Yates | DT15: 14 | DU15: 0 | DV15: =SUM(DT15:DU15) -> 14
... B28: 25 | C28: Guillaume Martin | D28: 1 | E28: 0 | F28: =SUM(D28:E28) -> 1 | H28: 25 | I28: Guillaume Martin | J28: 1 | K28: 0 | L28: =SUM(J28:K28) -> 1 | N28: 25 | O28: Oliver Naessen | P28: 1 | Q28: 0 | R28: =SUM(P28:Q28) -> 1 | T28: 25 | U28: Enric Mas | V28: 1 | W28: 0 | X28: =SUM(V28:W28) -> 1 | Z28: 25 | AA28: Cees Bol | AB28: 1 | AC28: 0 | AD28: =SUM(AB28:AC28) -> 1 | AF28: 25 | AG28: Michael Morkov | AH28: 1 | AI28: 0 | AJ28: =SUM(AH28:AI28) -> 1 | AL28: 25 | AM28: Raul Garcia | AN28: 1 | AO28: 0 | AP28: =SUM(AN28:AO28) -> 1 | AR28: 25 | AS28: Dylan Groenewegen | AT28: 1 | AU28: 0 | AV28: =SUM(AT28:AU28) -> 1 | AX28: 25 | AY28: Aleksandr Vlasov | AZ28: 1 | BA28: 0 | BB28: =SUM(AZ28:BA28) -> 1 | BD28: 25 | BE28: Daniel Mclay | BF28: 1 | BG28: 0 | BH28: =SUM(BF28:BG28) -> 1 | BJ28: 25 | BK28: Jai Hindley | BL28: 1 | BM28: 0 | BN28: =SUM(BL28:BM28) -> 1 | BP28: 25 | BQ28: Tiesj Bennoot | BR28: 1 | BS28: 0 | BT28: =SUM(BR28:BS28) -> 1 | BV28: 25 | BW28: Georg Zimmermann | BX28: 1 | BY28: 0 | BZ28: =SUM(BX28:BY28) -> 1 | CB28: 25 | CC28: Wilco Kelderman | CD28: 1 | CE28: 0 | CF28: =SUM(CD28:CE28) -> 1 | CH28: 25 | CI28: Wilco Kelderman | CJ28: 1 | CK28: 0 | CL28: =SUM(CJ28:CK28) -> 1 | CN28: 25 | CO28: Daniel Mclay | CP28: 1 | CQ28: 0 | CR28: =SUM(CP28:CQ28) -> 1 | CT28: 25 | CU28: Romain Gregoire | CV28: 1 | CW28: 0 | CX28: =SUM(CV28:CW28) -> 1 | CZ28: 25 | DA28: Sean Quinn | DB28: 1 | DC28: 0 | DD28: =SUM(DB28:DC28) -> 1 | DF28: 25 | DG28: Valentin Madouas | DH28: 1 | DI28: 0 | DJ28: =SUM(DH28:DI28) -> 1 | DL28: 25 | DM28: Louis Meintjes | DN28: 1 | DO28: 0 | DP28: =SUM(DN28:DO28) -> 1 | DR28: 25 | DS28: Enric Mas | DT28: 1 | DU28: 0 | DV28: =SUM(DT28:DU28) -> 1
A29: Truien Extra | C29: Jonas Abrahamsen | E29: 10 | F29: 10 | O29: Jonas Abrahamsen | Q29: 20 | R29: 20 | U29: Jonas Abrahamsen | W29: 20 | X29: 20 | AA29: Tadej Pogacar | AC29: 10 | AD29: 10 | AG29: Tadej Pogacar | AI29: 10 | AJ29: 10 | AM29: Biniam Girmay | AO29: 10 | AP29: 10 | AS29: Jonas Abrahamsen | AU29: 10 | AV29: 10 | AY29: Remco Evenepoel | BA29: 10 | BB29: 10 | BE29: Remco Evenepoel | BG29: 10 | BH29: 10 | BK29: Biniam Girmay | BM29: 10 | BN29: 10 | BQ29: Remco Evenepoel | BS29: 10 | BT29: 10 | BW29: Remco Evenepoel | BY29: 10 | BZ29: 10 | CC29: Biniam Girmay | CE29: 10 | CF29: 10 | CI29: Biniam Girmay | CK29: 10 | CL29: 10 | CO29: Biniam Girmay | CQ29: 10 | CR29: 10 | CU29: Biniam Girmay | CW29: 10 | CX29: 10 | DA29: Biniam Girmay | DC29: 10 | DD29: 10 | DG29: Biniam Girmay | DI29: 10 | DJ29: 10 | DM29: Biniam Girmay | DO29: 10 | DP29: 10 | DS29: Biniam Girmay | DU29: 10 | DV29: 10
O30: Remco Evenepoel | Q30: 10 | R30: 10 | AA30: Jonas Abrahamsen | AC30: 10 | AD30: 10 | AG30: Remco Evenepoel | AI30: 10 | AJ30: 10 | AM30: Jonas Abrahamsen | AO30: 10 | AP30: 10 | AY30: Tadej Pogacar | BA30: 10 | BB30: 10 | BE30: Tadej Pogacar | BG30: 10 | BH30: 10 | CO30: Tadej Pogacar | CQ30: 20 | CR30: 20 | CU30: Tadej Pogacar | CW30: 20 | CX30: 20 | DA30: Tadej Pogacar | DC30: 20 | DD30: 20 | DS30: Richard Carapaz | DU30: 10 | DV30: 10
AA31: Remco Evenepoel | AC31: 10 | AD31: 10 | AG31: Jonas Abrahamsen | AI31: 10 | AJ31: 10 | BE31: Jonas Abrahamsen | BG31: 10 | BH31: 10 | CO31: Remco Evenepoel | CQ31: 10 | CR31: 10 | CU31: Remco Evenepoel | CW31: 10 | CX31: 10 | DA31: Remco Evenepoel | DC31: 10 | DD31: 10
B34: Totaliteit punten per renner overkoepelend | N34: Eindafrekening | R34: Totale afrekening per speler per klassement | W34: TOTAAL Afrekening
C35: Naam | D35: Totaal | F35: Totaal gesorteerd | N35: Algemeen klassement | R35: Algemeen klassement | W35: Roel | X35: =SUM(T36,T42,T48,T57) -> 839
B36: 1 | C36: {=_xlfn.UNIQUE(_xlfn.VSTACK($C$4:$C$28,$I$4:$I$30,$O$4:$O$30,$U$4:$U$30,$AA$4:$AA$30,$AG$4:$AG$30,$AM$4:$AM$30,$AS$4:$AS$30,$AY$4:$AY$30,$BE$4:$BE$29,$BK$4:$BK$31,$BQ$4:$BQ$32,$BW$4:$BW$32,$CC$4:$CC$32,$CI$4:$CI$32,$CO$4:$CO$32,$CU$4:$CU$32,$DA$4:$DA$32,$DG$4:$DG$32,$DM$4:$DM$32,$DS$4:$DS$32))} -> Romain Bardet | D36: =_xlfn.IFNA(VLOOKUP(C36,$I$4:$L$30,4,FALSE),0)+_xlfn.IFNA(VLOOKUP(C36,$C$4:$F$28,4,FALSE),0)+_xlfn.IFNA(VLOOKUP(C36,$U$4:$X$30,4,FALSE),0)+_xlfn.IFNA(VLOOKUP(C36,$O$4:$R$30,4,FALSE),0)+_xlfn.IFNA(VLOOKUP(C36,$AA$4:$AD$30,4,FALSE),0)+_xlfn.IFNA(VLOOKUP(C36,$AG$4:$AJ$30,4,FALSE),0)+_xlfn.IFNA(VLOOKUP(C36,$AM$4:$AP$30,4,FALSE),0)+_xlfn.IFNA(VLOOKUP(C36,$AS$4:$AV$30,4,FALSE),0)+_xlfn.IFNA(VLOOKUP(C36,$AY$4:$BB$30,4,FALSE),0)+_xlfn.IFNA(VLOOKUP(C36,$BE$4:$BH$29,4,FALSE),0)+_xlfn.IFNA(VLOOKUP(C36,$BK$4:$BN$31,4,FALSE),0)+_xlfn.IFNA(VLOOKUP(C36,$BQ$4:$BT$32,4,FALSE),0)+_xlfn.IFNA(VLOOKUP(C36,$BW$4:$BZ$32,4,FALSE),0)+_xlfn.IFNA(VLOOKUP(C36,$CC$4:$CF$32,4,FALSE),0)+_xlfn.IFNA(VLOOKUP(C36,$CI$4:$CL$32,4,FALSE),0)+_xlfn.IFNA(VLOOKUP(C36,$CO$4:$CR$32,4,FALSE),0)+_xlfn.IFNA(VLOOKUP(C36,$CU$4:$CX$32,4,FALSE),0)+_xlfn.IFNA(VLOOKUP(C36,$DA$4:$DD$32,4,FALSE),0)+_xlfn.IFNA(VLOOKUP(C36,$DG$4:$DJ$32,4,FALSE),0)+_xlfn.IFNA(VLOOKUP(C36,$DM$4:$DP$32,4,FALSE),0)+_xlfn.IFNA(VLOOKUP(C36,$DS$4:$DV$32,4,FALSE),0) -> 137 | F36: {=_xlfn._xlws.SORT($C$36:$D$303,2,-1,FALSE)} -> Tadej Pogacar | G36: 1123 | N36: Positie | O36: Naam | P36: Punten | R36: Roel | S36: 4 | T36: 564 | W36: Jonas | X36: =SUM(T37,T43,T50,T54) -> 623
B37: 2 | C37: Frank Van Den Broek | D37: =_xlfn.IFNA(VLOOKUP(C37,$I$4:$L$30,4,FALSE),0)+_xlfn.IFNA(VLOOKUP(C37,$C$4:$F$28,4,FALSE),0)+_xlfn.IFNA(VLOOKUP(C37,$U$4:$X$30,4,FALSE),0)+_xlfn.IFNA(VLOOKUP(C37,$O$4:$R$30,4,FALSE),0)+_xlfn.IFNA(VLOOKUP(C37,$AA$4:$AD$30,4,FALSE),0)+_xlfn.IFNA(VLOOKUP(C37,$AG$4:$AJ$30,4,FALSE),0)+_xlfn.IFNA(VLOOKUP(C37,$AM$4:$AP$30,4,FALSE),0)+_xlfn.IFNA(VLOOKUP(C37,$AS$4:$AV$30,4,FALSE),0)+_xlfn.IFNA(VLOOKUP(C37,$AY$4:$BB$30,4,FALSE),0)+_xlfn.IFNA(VLOOKUP(C37,$BE$4:$BH$29,4,FALSE),0)+_xlfn.IFNA(VLOOKUP(C37,$BK$4:$BN$31,4,FALSE),0)+_xlfn.IFNA(VLOOKUP(C37,$BQ$4:$BT$32,4,FALSE),0)+_xlfn.IFNA(VLOOKUP(C37,$BW$4:$BZ$32,4,FALSE),0)+_xlfn.IFNA(VLOOKUP(C37,$CC$4:$CF$32,4,FALSE),0)+_xlfn.IFNA(VLOOKUP(C37,$CI$4:$CL$32,4,FALSE),0)+_xlfn.IFNA(VLOOKUP(C37,$CO$4:$CR$32,4,FALSE),0)+_xlfn.IFNA(VLOOKUP(C37,$CU$4:$CX$32,4,FALSE),0)+_xlfn.IFNA(VLOOKUP(C37,$DA$4:$DD$32,4,FALSE),0)+_xlfn.IFNA(VLOOKUP(C37,$DG$4:$DJ$32,4,FALSE),0)+_xlfn.IFNA(VLOOKUP(C37,$DM$4:$DP$32,4,FALSE),0)+_xlfn.IFNA(VLOOKUP(C37,$DS$4:$DV$32,4,FALSE),0) -> 105 | F37: Remco Evenepoel | G37: 786 | N37: 1 | O37: Tadej Pogacar | P37: 300 | R37: Jonas | S37: 4 | T37: 378 | W37: Casper | X37: =SUM(T38,T45,T51,T55) -> 641
B38: 3 | C38: Wout Van Aert | D38: =_xlfn.IFNA(VLOOKUP(C38,$I$4:$L$30,4,FALSE),0)+_xlfn.IFNA(VLOOKUP(C38,$C$4:$F$28,4,FALSE),0)+_xlfn.IFNA(VLOOKUP(C38,$U$4:$X$30,4,FALSE),0)+_xlfn.IFNA(VLOOKUP(C38,$O$4:$R$30,4,FALSE),0)+_xlfn.IFNA(VLOOKUP(C38,$AA$4:$AD$30,4,FALSE),0)+_xlfn.IFNA(VLOOKUP(C38,$AG$4:$AJ$30,4,FALSE),0)+_xlfn.IFNA(VLOOKUP(C38,$AM$4:$AP$30,4,FALSE),0)+_xlfn.IFNA(VLOOKUP(C38,$AS$4:$AV$30,4,FALSE),0)+_xlfn.IFNA(VLOOKUP(C38,$AY$4:$BB$30,4,FALSE),0)+_xlfn.IFNA(VLOOKUP(C38,$BE$4:$BH$29,4,FALSE),0)+_xlfn.IFNA(VLOOKUP(C38,$BK$4:$BN$31,4,FALSE),0)+_xlfn.IFNA(VLOOKUP(C38,$BQ$4:$BT$32,4,FALSE),0)+_xlfn.IFNA(VLOOKUP(C38,$BW$4:$BZ$32,4,FALSE),0)+_xlfn.IFNA(VLOOKUP(C38,$CC$4:$CF$32,4,FALSE),0)+_xlfn.IFNA(VLOOKUP(C38,$CI$4:$CL$32,4,FALSE),0)+_xlfn.IFNA(VLOOKUP(C38,$CO$4:$CR$32,4,FALSE),0)+_xlfn.IFNA(VLOOKUP(C38,$CU$4:$CX$32,4,FALSE),0)+_xlfn.IFNA(VLOOKUP(C38,$DA$4:$DD$32,4,FALSE),0)+_xlfn.IFNA(VLOOKUP(C38,$DG$4:$DJ$32,4,FALSE),0)+_xlfn.IFNA(VLOOKUP(C38,$DM$4:$DP$32,4,FALSE),0)+_xlfn.IFNA(VLOOKUP(C38,$DS$4:$DV$32,4,FALSE),0) -> 382 | F38: Biniam Girmay | G38: 725 | N38: 2 | O38: Jonas Vingegaard | P38: 240 | R38: Casper | S38: 6 | T38: 324 | W38: Dries | X38: =SUM(T39,T44,T49,T56) -> 642
B39: 4 | C39: Tadej Pogacar | D39: =_xlfn.IFNA(VLOOKUP(C39,$I$4:$L$30,4,FALSE),0)+_xlfn.IFNA(VLOOKUP(C39,$C$4:$F$28,4,FALSE),0)+_xlfn.IFNA(VLOOKUP(C39,$U$4:$X$30,4,FALSE),0)+_xlfn.IFNA(VLOOKUP(C39,$O$4:$R$30,4,FALSE),0)+_xlfn.IFNA(VLOOKUP(C39,$AA$4:$AD$30,4,FALSE),0)+_xlfn.IFNA(VLOOKUP(C39,$AG$4:$AJ$30,4,FALSE),0)+_xlfn.IFNA(VLOOKUP(C39,$AM$4:$AP$30,4,FALSE),0)+_xlfn.IFNA(VLOOKUP(C39,$AS$4:$AV$30,4,FALSE),0)+_xlfn.IFNA(VLOOKUP(C39,$AY$4:$BB$30,4,FALSE),0)+_xlfn.IFNA(VLOOKUP(C39,$BE$4:$BH$29,4,FALSE),0)+_xlfn.IFNA(VLOOKUP(C39,$BK$4:$BN$31,4,FALSE),0)+_xlfn.IFNA(VLOOKUP(C39,$BQ$4:$BT$32,4,FALSE),0)+_xlfn.IFNA(VLOOKUP(C39,$BW$4:$BZ$32,4,FALSE),0)+_xlfn.IFNA(VLOOKUP(C39,$CC$4:$CF$32,4,FALSE),0)+_xlfn.IFNA(VLOOKUP(C39,$CI$4:$CL$32,4,FALSE),0)+_xlfn.IFNA(VLOOKUP(C39,$CO$4:$CR$32,4,FALSE),0)+_xlfn.IFNA(VLOOKUP(C39,$CU$4:$CX$32,4,FALSE),0)+_xlfn.IFNA(VLOOKUP(C39,$DA$4:$DD$32,4,FALSE),0)+_xlfn.IFNA(VLOOKUP(C39,$DG$4:$DJ$32,4,FALSE),0)+_xlfn.IFNA(VLOOKUP(C39,$DM$4:$DP$32,4,FALSE),0)+_xlfn.IFNA(VLOOKUP(C39,$DS$4:$DV$32,4,FALSE),0) -> 1123 | F39: Jonas Vingegaard | G39: 578 | N39: 3 | O39: Remco Evenepoel | P39: 195 | R39: Dries | S39: 3 | T39: 357
B40: 5 | C40: Maxim Van Gils | D40: =_xlfn.IFNA(VLOOKUP(C40,$I$4:$L$30,4,FALSE),0)+_xlfn.IFNA(VLOOKUP(C40,$C$4:$F$28,4,FALSE),0)+_xlfn.IFNA(VLOOKUP(C40,$U$4:$X$30,4,FALSE),0)+_xlfn.IFNA(VLOOKUP(C40,$O$4:$R$30,4,FALSE),0)+_xlfn.IFNA(VLOOKUP(C40,$AA$4:$AD$30,4,FALSE),0)+_xlfn.IFNA(VLOOKUP(C40,$AG$4:$AJ$30,4,FALSE),0)+_xlfn.IFNA(VLOOKUP(C40,$AM$4:$AP$30,4,FALSE),0)+_xlfn.IFNA(VLOOKUP(C40,$AS$4:$AV$30,4,FALSE),0)+_xlfn.IFNA(VLOOKUP(C40,$AY$4:$BB$30,4,FALSE),0)+_xlfn.IFNA(VLOOKUP(C40,$BE$4:$BH$29,4,FALSE),0)+_xlfn.IFNA(VLOOKUP(C40,$BK$4:$BN$31,4,FALSE),0)+_xlfn.IFNA(VLOOKUP(C40,$BQ$4:$BT$32,4,FALSE),0)+_xlfn.IFNA(VLOOKUP(C40,$BW$4:$BZ$32,4,FALSE),0)+_xlfn.IFNA(VLOOKUP(C40,$CC$4:$CF$32,4,FALSE),0)+_xlfn.IFNA(VLOOKUP(C40,$CI$4:$CL$32,4,FALSE),0)+_xlfn.IFNA(VLOOKUP(C40,$CO$4:$CR$32,4,FALSE),0)+_xlfn.IFNA(VLOOKUP(C40,$CU$4:$CX$32,4,FALSE),0)+_xlfn.IFNA(VLOOKUP(C40,$DA$4:$DD$32,4,FALSE),0)+_xlfn.IFNA(VLOOKUP(C40,$DG$4:$DJ$32,4,FALSE),0)+_xlfn.IFNA(VLOOKUP(C40,$DM$4:$DP$32,4,FALSE),0)+_xlfn.IFNA(VLOOKUP(C40,$DS$4:$DV$32,4,FALSE),0) -> 77 | F40: Jasper Philipsen | G40: 515 | N40: 4 | O40: Joao Almeida | P40: 165
B41: 6 | C41: Alex Aranburu | D41: =_xlfn.IFNA(VLOOKUP(C41,$I$4:$L$30,4,FALSE),0)+_xlfn.IFNA(VLOOKUP(C41,$C$4:$F$28,4,FALSE),0)+_xlfn.IFNA(VLOOKUP(C41,$U$4:$X$30,4,FALSE),0)+_xlfn.IFNA(VLOOKUP(C41,$O$4:$R$30,4,FALSE),0)+_xlfn.IFNA(VLOOKUP(C41,$AA$4:$AD$30,4,FALSE),0)+_xlfn.IFNA(VLOOKUP(C41,$AG$4:$AJ$30,4,FALSE),0)+_xlfn.IFNA(VLOOKUP(C41,$AM$4:$AP$30,4,FALSE),0)+_xlfn.IFNA(VLOOKUP(C41,$AS$4:$AV$30,4,FALSE),0)+_xlfn.IFNA(VLOOKUP(C41,$AY$4:$BB$30,4,FALSE),0)+_xlfn.IFNA(VLOOKUP(C41,$BE$4:$BH$29,4,FALSE),0)+_xlfn.IFNA(VLOOKUP(C41,$BK$4:$BN$31,4,FALSE),0)+_xlfn.IFNA(VLOOKUP(C41,$BQ$4:$BT$32,4,FALSE),0)+_xlfn.IFNA(VLOOKUP(C41,$BW$4:$BZ$32,4,FALSE),0)+_xlfn.IFNA(VLOOKUP(C41,$CC$4:$CF$32,4,FALSE),0)+_xlfn.IFNA(VLOOKUP(C41,$CI$4:$CL$32,4,FALSE),0)+_xlfn.IFNA(VLOOKUP(C41,$CO$4:$CR$32,4,FALSE),0)+_xlfn.IFNA(VLOOKUP(C41,$CU$4:$CX$32,4,FALSE),0)+_xlfn.IFNA(VLOOKUP(C41,$DA$4:$DD$32,4,FALSE),0)+_xlfn.IFNA(VLOOKUP(C41,$DG$4:$DJ$32,4,FALSE),0)+_xlfn.IFNA(VLOOKUP(C41,$DM$4:$DP$32,4,FALSE),0)+_xlfn.IFNA(VLOOKUP(C41,$DS$4:$DV$32,4,FALSE),0) -> 139 | F41: Wout Van Aert | G41: 382 | N41: 5 | O41: Mikel Landa | P41: 135 | R41: Bergtrui
B42: 7 | C42: Mads Pedersen | D42: =_xlfn.IFNA(VLOOKUP(C42,$I$4:$L$30,4,FALSE),0)+_xlfn.IFNA(VLOOKUP(C42,$C$4:$F$28,4,FALSE),0)+_xlfn.IFNA(VLOOKUP(C42,$U$4:$X$30,4,FALSE),0)+_xlfn.IFNA(VLOOKUP(C42,$O$4:$R$30,4,FALSE),0)+_xlfn.IFNA(VLOOKUP(C42,$AA$4:$AD$30,4,FALSE),0)+_xlfn.IFNA(VLOOKUP(C42,$AG$4:$AJ$30,4,FALSE),0)+_xlfn.IFNA(VLOOKUP(C42,$AM$4:$AP$30,4,FALSE),0)+_xlfn.IFNA(VLOOKUP(C42,$AS$4:$AV$30,4,FALSE),0)+_xlfn.IFNA(VLOOKUP(C42,$AY$4:$BB$30,4,FALSE),0)+_xlfn.IFNA(VLOOKUP(C42,$BE$4:$BH$29,4,FALSE),0)+_xlfn.IFNA(VLOOKUP(C42,$BK$4:$BN$31,4,FALSE),0)+_xlfn.IFNA(VLOOKUP(C42,$BQ$4:$BT$32,4,FALSE),0)+_xlfn.IFNA(VLOOKUP(C42,$BW$4:$BZ$32,4,FALSE),0)+_xlfn.IFNA(VLOOKUP(C42,$CC$4:$CF$32,4,FALSE),0)+_xlfn.IFNA(VLOOKUP(C42,$CI$4:$CL$32,4,FALSE),0)+_xlfn.IFNA(VLOOKUP(C42,$CO$4:$CR$32,4,FALSE),0)+_xlfn.IFNA(VLOOKUP(C42,$CU$4:$CX$32,4,FALSE),0)+_xlfn.IFNA(VLOOKUP(C42,$DA$4:$DD$32,4,FALSE),0)+_xlfn.IFNA(VLOOKUP(C42,$DG$4:$DJ$32,4,FALSE),0)+_xlfn.IFNA(VLOOKUP(C42,$DM$4:$DP$32,4,FALSE),0)+_xlfn.IFNA(VLOOKUP(C42,$DS$4:$DV$32,4,FALSE),0) -> 96 | F42: Pascal Ackermann | G42: 361 | I42: Bankpunten klassement | N42: 6 | O42: Adam Yates | P42: 105 | R42: Roel | S42: 3 | T42: 135
B43: 8 | C43: Remco Evenepoel | D43: =_xlfn.IFNA(VLOOKUP(C43,$I$4:$L$30,4,FALSE),0)+_xlfn.IFNA(VLOOKUP(C43,$C$4:$F$28,4,FALSE),0)+_xlfn.IFNA(VLOOKUP(C43,$U$4:$X$30,4,FALSE),0)+_xlfn.IFNA(VLOOKUP(C43,$O$4:$R$30,4,FALSE),0)+_xlfn.IFNA(VLOOKUP(C43,$AA$4:$AD$30,4,FALSE),0)+_xlfn.IFNA(VLOOKUP(C43,$AG$4:$AJ$30,4,FALSE),0)+_xlfn.IFNA(VLOOKUP(C43,$AM$4:$AP$30,4,FALSE),0)+_xlfn.IFNA(VLOOKUP(C43,$AS$4:$AV$30,4,FALSE),0)+_xlfn.IFNA(VLOOKUP(C43,$AY$4:$BB$30,4,FALSE),0)+_xlfn.IFNA(VLOOKUP(C43,$BE$4:$BH$29,4,FALSE),0)+_xlfn.IFNA(VLOOKUP(C43,$BK$4:$BN$31,4,FALSE),0)+_xlfn.IFNA(VLOOKUP(C43,$BQ$4:$BT$32,4,FALSE),0)+_xlfn.IFNA(VLOOKUP(C43,$BW$4:$BZ$32,4,FALSE),0)+_xlfn.IFNA(VLOOKUP(C43,$CC$4:$CF$32,4,FALSE),0)+_xlfn.IFNA(VLOOKUP(C43,$CI$4:$CL$32,4,FALSE),0)+_xlfn.IFNA(VLOOKUP(C43,$CO$4:$CR$32,4,FALSE),0)+_xlfn.IFNA(VLOOKUP(C43,$CU$4:$CX$32,4,FALSE),0)+_xlfn.IFNA(VLOOKUP(C43,$DA$4:$DD$32,4,FALSE),0)+_xlfn.IFNA(VLOOKUP(C43,$DG$4:$DJ$32,4,FALSE),0)+_xlfn.IFNA(VLOOKUP(C43,$DM$4:$DP$32,4,FALSE),0)+_xlfn.IFNA(VLOOKUP(C43,$DS$4:$DV$32,4,FALSE),0) -> 786 | F43: Richard Carapaz | G43: 321 | I43: Jonas | N43: 7 | O43: Carlos Rodriguez | P43: 90 | R43: Jonas | S43: 2 | T43: 75
B44: 9 | C44: Pello Bilbao | D44: =_xlfn.IFNA(VLOOKUP(C44,$I$4:$L$30,4,FALSE),0)+_xlfn.IFNA(VLOOKUP(C44,$C$4:$F$28,4,FALSE),0)+_xlfn.IFNA(VLOOKUP(C44,$U$4:$X$30,4,FALSE),0)+_xlfn.IFNA(VLOOKUP(C44,$O$4:$R$30,4,FALSE),0)+_xlfn.IFNA(VLOOKUP(C44,$AA$4:$AD$30,4,FALSE),0)+_xlfn.IFNA(VLOOKUP(C44,$AG$4:$AJ$30,4,FALSE),0)+_xlfn.IFNA(VLOOKUP(C44,$AM$4:$AP$30,4,FALSE),0)+_xlfn.IFNA(VLOOKUP(C44,$AS$4:$AV$30,4,FALSE),0)+_xlfn.IFNA(VLOOKUP(C44,$AY$4:$BB$30,4,FALSE),0)+_xlfn.IFNA(VLOOKUP(C44,$BE$4:$BH$29,4,FALSE),0)+_xlfn.IFNA(VLOOKUP(C44,$BK$4:$BN$31,4,FALSE),0)+_xlfn.IFNA(VLOOKUP(C44,$BQ$4:$BT$32,4,FALSE),0)+_xlfn.IFNA(VLOOKUP(C44,$BW$4:$BZ$32,4,FALSE),0)+_xlfn.IFNA(VLOOKUP(C44,$CC$4:$CF$32,4,FALSE),0)+_xlfn.IFNA(VLOOKUP(C44,$CI$4:$CL$32,4,FALSE),0)+_xlfn.IFNA(VLOOKUP(C44,$CO$4:$CR$32,4,FALSE),0)+_xlfn.IFNA(VLOOKUP(C44,$CU$4:$CX$32,4,FALSE),0)+_xlfn.IFNA(VLOOKUP(C44,$DA$4:$DD$32,4,FALSE),0)+_xlfn.IFNA(VLOOKUP(C44,$DG$4:$DJ$32,4,FALSE),0)+_xlfn.IFNA(VLOOKUP(C44,$DM$4:$DP$32,4,FALSE),0)+_xlfn.IFNA(VLOOKUP(C44,$DS$4:$DV$32,4,FALSE),0) -> 31 | F44: Arnaud De Lie | G44: 284 | I44: Casper | N44: 8 | O44: Matteo Jorgenson | P44: 75 | R44: Dries | S44: 2 | T44: 130
B45: 10 | C45: Alberto Bettiol | D45: =_xlfn.IFNA(VLOOKUP(C45,$I$4:$L$30,4,FALSE),0)+_xlfn.IFNA(VLOOKUP(C45,$C$4:$F$28,4,FALSE),0)+_xlfn.IFNA(VLOOKUP(C45,$U$4:$X$30,4,FALSE),0)+_xlfn.IFNA(VLOOKUP(C45,$O$4:$R$30,4,FALSE),0)+_xlfn.IFNA(VLOOKUP(C45,$AA$4:$AD$30,4,FALSE),0)+_xlfn.IFNA(VLOOKUP(C45,$AG$4:$AJ$30,4,FALSE),0)+_xlfn.IFNA(VLOOKUP(C45,$AM$4:$AP$30,4,FALSE),0)+_xlfn.IFNA(VLOOKUP(C45,$AS$4:$AV$30,4,FALSE),0)+_xlfn.IFNA(VLOOKUP(C45,$AY$4:$BB$30,4,FALSE),0)+_xlfn.IFNA(VLOOKUP(C45,$BE$4:$BH$29,4,FALSE),0)+_xlfn.IFNA(VLOOKUP(C45,$BK$4:$BN$31,4,FALSE),0)+_xlfn.IFNA(VLOOKUP(C45,$BQ$4:$BT$32,4,FALSE),0)+_xlfn.IFNA(VLOOKUP(C45,$BW$4:$BZ$32,4,FALSE),0)+_xlfn.IFNA(VLOOKUP(C45,$CC$4:$CF$32,4,FALSE),0)+_xlfn.IFNA(VLOOKUP(C45,$CI$4:$CL$32,4,FALSE),0)+_xlfn.IFNA(VLOOKUP(C45,$CO$4:$CR$32,4,FALSE),0)+_xlfn.IFNA(VLOOKUP(C45,$CU$4:$CX$32,4,FALSE),0)+_xlfn.IFNA(VLOOKUP(C45,$DA$4:$DD$32,4,FALSE),0)+_xlfn.IFNA(VLOOKUP(C45,$DG$4:$DJ$32,4,FALSE),0)+_xlfn.IFNA(VLOOKUP(C45,$DM$4:$DP$32,4,FALSE),0)+_xlfn.IFNA(VLOOKUP(C45,$DS$4:$DV$32,4,FALSE),0) -> 17 | F45: Matteo Jorgenson | G45: 259 | I45: Roel | N45: 9 | O45: Derek Gee | P45: 60 | R45: Casper | S45: 1 | T45: 5
B46: 11 | C46: Tom Pidcock | D46: =_xlfn.IFNA(VLOOKUP(C46,$I$4:$L$30,4,FALSE),0)+_xlfn.IFNA(VLOOKUP(C46,$C$4:$F$28,4,FALSE),0)+_xlfn.IFNA(VLOOKUP(C46,$U$4:$X$30,4,FALSE),0)+_xlfn.IFNA(VLOOKUP(C46,$O$4:$R$30,4,FALSE),0)+_xlfn.IFNA(VLOOKUP(C46,$AA$4:$AD$30,4,FALSE),0)+_xlfn.IFNA(VLOOKUP(C46,$AG$4:$AJ$30,4,FALSE),0)+_xlfn.IFNA(VLOOKUP(C46,$AM$4:$AP$30,4,FALSE),0)+_xlfn.IFNA(VLOOKUP(C46,$AS$4:$AV$30,4,FALSE),0)+_xlfn.IFNA(VLOOKUP(C46,$AY$4:$BB$30,4,FALSE),0)+_xlfn.IFNA(VLOOKUP(C46,$BE$4:$BH$29,4,FALSE),0)+_xlfn.IFNA(VLOOKUP(C46,$BK$4:$BN$31,4,FALSE),0)+_xlfn.IFNA(VLOOKUP(C46,$BQ$4:$BT$32,4,FALSE),0)+_xlfn.IFNA(VLOOKUP(C46,$BW$4:$BZ$32,4,FALSE),0)+_xlfn.IFNA(VLOOKUP(C46,$CC$4:$CF$32,4,FALSE),0)+_xlfn.IFNA(VLOOKUP(C46,$CI$4:$CL$32,4,FALSE),0)+_xlfn.IFNA(VLOOKUP(C46,$CO$4:$CR$32,4,FALSE),0)+_xlfn.IFNA(VLOOKUP(C46,$CU$4:$CX$32,4,FALSE),0)+_xlfn.IFNA(VLOOKUP(C46,$DA$4:$DD$32,4,FALSE),0)+_xlfn.IFNA(VLOOKUP(C46,$DG$4:$DJ$32,4,FALSE),0)+_xlfn.IFNA(VLOOKUP(C46,$DM$4:$DP$32,4,FALSE),0)+_xlfn.IFNA(VLOOKUP(C46,$DS$4:$DV$32,4,FALSE),0) -> 95 | F46: Joao Almeida | G46: 254 | I46: Dries | N46: 10 | O46: Santiago Buitrago | P46: 51
B47: 12 | C47: Egan Bernal | D47: =_xlfn.IFNA(VLOOKUP(C47,$I$4:$L$30,4,FALSE),0)+_xlfn.IFNA(VLOOKUP(C47,$C$4:$F$28,4,FALSE),0)+_xlfn.IFNA(VLOOKUP(C47,$U$4:$X$30,4,FALSE),0)+_xlfn.IFNA(VLOOKUP(C47,$O$4:$R$30,4,FALSE),0)+_xlfn.IFNA(VLOOKUP(C47,$AA$4:$AD$30,4,FALSE),0)+_xlfn.IFNA(VLOOKUP(C47,$AG$4:$AJ$30,4,FALSE),0)+_xlfn.IFNA(VLOOKUP(C47,$AM$4:$AP$30,4,FALSE),0)+_xlfn.IFNA(VLOOKUP(C47,$AS$4:$AV$30,4,FALSE),0)+_xlfn.IFNA(VLOOKUP(C47,$AY$4:$BB$30,4,FALSE),0)+_xlfn.IFNA(VLOOKUP(C47,$BE$4:$BH$29,4,FALSE),0)+_xlfn.IFNA(VLOOKUP(C47,$BK$4:$BN$31,4,FALSE),0)+_xlfn.IFNA(VLOOKUP(C47,$BQ$4:$BT$32,4,FALSE),0)+_xlfn.IFNA(VLOOKUP(C47,$BW$4:$BZ$32,4,FALSE),0)+_xlfn.IFNA(VLOOKUP(C47,$CC$4:$CF$32,4,FALSE),0)+_xlfn.IFNA(VLOOKUP(C47,$CI$4:$CL$32,4,FALSE),0)+_xlfn.IFNA(VLOOKUP(C47,$CO$4:$CR$32,4,FALSE),0)+_xlfn.IFNA(VLOOKUP(C47,$CU$4:$CX$32,4,FALSE),0)+_xlfn.IFNA(VLOOKUP(C47,$DA$4:$DD$32,4,FALSE),0)+_xlfn.IFNA(VLOOKUP(C47,$DG$4:$DJ$32,4,FALSE),0)+_xlfn.IFNA(VLOOKUP(C47,$DM$4:$DP$32,4,FALSE),0)+_xlfn.IFNA(VLOOKUP(C47,$DS$4:$DV$32,4,FALSE),0) -> 44 | F47: Fernando Gaviria | G47: 227 | N47: 11 | O47: Giulio Ciccone | P47: 45 | R47: Puntentrui
B48: 13 | C48: Ilan Van Wilder | D48: =_xlfn.IFNA(VLOOKUP(C48,$I$4:$L$30,4,FALSE),0)+_xlfn.IFNA(VLOOKUP(C48,$C$4:$F$28,4,FALSE),0)+_xlfn.IFNA(VLOOKUP(C48,$U$4:$X$30,4,FALSE),0)+_xlfn.IFNA(VLOOKUP(C48,$O$4:$R$30,4,FALSE),0)+_xlfn.IFNA(VLOOKUP(C48,$AA$4:$AD$30,4,FALSE),0)+_xlfn.IFNA(VLOOKUP(C48,$AG$4:$AJ$30,4,FALSE),0)+_xlfn.IFNA(VLOOKUP(C48,$AM$4:$AP$30,4,FALSE),0)+_xlfn.IFNA(VLOOKUP(C48,$AS$4:$AV$30,4,FALSE),0)+_xlfn.IFNA(VLOOKUP(C48,$AY$4:$BB$30,4,FALSE),0)+_xlfn.IFNA(VLOOKUP(C48,$BE$4:$BH$29,4,FALSE),0)+_xlfn.IFNA(VLOOKUP(C48,$BK$4:$BN$31,4,FALSE),0)+_xlfn.IFNA(VLOOKUP(C48,$BQ$4:$BT$32,4,FALSE),0)+_xlfn.IFNA(VLOOKUP(C48,$BW$4:$BZ$32,4,FALSE),0)+_xlfn.IFNA(VLOOKUP(C48,$CC$4:$CF$32,4,FALSE),0)+_xlfn.IFNA(VLOOKUP(C48,$CI$4:$CL$32,4,FALSE),0)+_xlfn.IFNA(VLOOKUP(C48,$CO$4:$CR$32,4,FALSE),0)+_xlfn.IFNA(VLOOKUP(C48,$CU$4:$CX$32,4,FALSE),0)+_xlfn.IFNA(VLOOKUP(C48,$DA$4:$DD$32,4,FALSE),0)+_xlfn.IFNA(VLOOKUP(C48,$DG$4:$DJ$32,4,FALSE),0)+_xlfn.IFNA(VLOOKUP(C48,$DM$4:$DP$32,4,FALSE),0)+_xlfn.IFNA(VLOOKUP(C48,$DS$4:$DV$32,4,FALSE),0) -> 48 | F48: Phil Bauhaus | G48: 225 | N48: 12 | O48: Simon Yates | P48: 42 | R48: Roel | S48: 2 | T48: 100
B49: 14 | C49: Victor Campenaerts | D49: =_xlfn.IFNA(VLOOKUP(C49,$I$4:$L$30,4,FALSE),0)+_xlfn.IFNA(VLOOKUP(C49,$C$4:$F$28,4,FALSE),0)+_xlfn.IFNA(VLOOKUP(C49,$U$4:$X$30,4,FALSE),0)+_xlfn.IFNA(VLOOKUP(C49,$O$4:$R$30,4,FALSE),0)+_xlfn.IFNA(VLOOKUP(C49,$AA$4:$AD$30,4,FALSE),0)+_xlfn.IFNA(VLOOKUP(C49,$AG$4:$AJ$30,4,FALSE),0)+_xlfn.IFNA(VLOOKUP(C49,$AM$4:$AP$30,4,FALSE),0)+_xlfn.IFNA(VLOOKUP(C49,$AS$4:$AV$30,4,FALSE),0)+_xlfn.IFNA(VLOOKUP(C49,$AY$4:$BB$30,4,FALSE),0)+_xlfn.IFNA(VLOOKUP(C49,$BE$4:$BH$29,4,FALSE),0)+_xlfn.IFNA(VLOOKUP(C49,$BK$4:$BN$31,4,FALSE),0)+_xlfn.IFNA(VLOOKUP(C49,$BQ$4:$BT$32,4,FALSE),0)+_xlfn.IFNA(VLOOKUP(C49,$BW$4:$BZ$32,4,FALSE),0)+_xlfn.IFNA(VLOOKUP(C49,$CC$4:$CF$32,4,FALSE),0)+_xlfn.IFNA(VLOOKUP(C49,$CI$4:$CL$32,4,FALSE),0)+_xlfn.IFNA(VLOOKUP(C49,$CO$4:$CR$32,4,FALSE),0)+_xlfn.IFNA(VLOOKUP(C49,$CU$4:$CX$32,4,FALSE),0)+_xlfn.IFNA(VLOOKUP(C49,$DA$4:$DD$32,4,FALSE),0)+_xlfn.IFNA(VLOOKUP(C49,$DG$4:$DJ$32,4,FALSE),0)+_xlfn.IFNA(VLOOKUP(C49,$DM$4:$DP$32,4,FALSE),0)+_xlfn.IFNA(VLOOKUP(C49,$DS$4:$DV$32,4,FALSE),0) -> 170 | F49: Alexander Kristoff | G49: 214 | N49: 13 | O49: Guillaume Martin | P49: 39 | R49: Dries | S49: 2 | T49: 70
B50: 15 | C50: Jai Hindley | D50: =_xlfn.IFNA(VLOOKUP(C50,$I$4:$L$30,4,FALSE),0)+_xlfn.IFNA(VLOOKUP(C50,$C$4:$F$28,4,FALSE),0)+_xlfn.IFNA(VLOOKUP(C50,$U$4:$X$30,4,FALSE),0)+_xlfn.IFNA(VLOOKUP(C50,$O$4:$R$30,4,FALSE),0)+_xlfn.IFNA(VLOOKUP(C50,$AA$4:$AD$30,4,FALSE),0)+_xlfn.IFNA(VLOOKUP(C50,$AG$4:$AJ$30,4,FALSE),0)+_xlfn.IFNA(VLOOKUP(C50,$AM$4:$AP$30,4,FALSE),0)+_xlfn.IFNA(VLOOKUP(C50,$AS$4:$AV$30,4,FALSE),0)+_xlfn.IFNA(VLOOKUP(C50,$AY$4:$BB$30,4,FALSE),0)+_xlfn.IFNA(VLOOKUP(C50,$BE$4:$BH$29,4,FALSE),0)+_xlfn.IFNA(VLOOKUP(C50,$BK$4:$BN$31,4,FALSE),0)+_xlfn.IFNA(VLOOKUP(C50,$BQ$4:$BT$32,4,FALSE),0)+_xlfn.IFNA(VLOOKUP(C50,$BW$4:$BZ$32,4,FALSE),0)+_xlfn.IFNA(VLOOKUP(C50,$CC$4:$CF$32,4,FALSE),0)+_xlfn.IFNA(VLOOKUP(C50,$CI$4:$CL$32,4,FALSE),0)+_xlfn.IFNA(VLOOKUP(C50,$CO$4:$CR$32,4,FALSE),0)+_xlfn.IFNA(VLOOKUP(C50,$CU$4:$CX$32,4,FALSE),0)+_xlfn.IFNA(VLOOKUP(C50,$DA$4:$DD$32,4,FALSE),0)+_xlfn.IFNA(VLOOKUP(C50,$DG$4:$DJ$32,4,FALSE),0)+_xlfn.IFNA(VLOOKUP(C50,$DM$4:$DP$32,4,FALSE),0)+_xlfn.IFNA(VLOOKUP(C50,$DS$4:$DV$32,4,FALSE),0) -> 64 | F50: Derek Gee | G50: 209 | N50: 14 | O50: Felix Gall | P50: 36 | R50: Jonas | S50: 2 | T50: 155
B51: 16 | C51: Jonas Vingegaard | D51: =_xlfn.IFNA(VLOOKUP(C51,$I$4:$L$30,4,FALSE),0)+_xlfn.IFNA(VLOOKUP(C51,$C$4:$F$28,4,FALSE),0)+_xlfn.IFNA(VLOOKUP(C51,$U$4:$X$30,4,FALSE),0)+_xlfn.IFNA(VLOOKUP(C51,$O$4:$R$30,4,FALSE),0)+_xlfn.IFNA(VLOOKUP(C51,$AA$4:$AD$30,4,FALSE),0)+_xlfn.IFNA(VLOOKUP(C51,$AG$4:$AJ$30,4,FALSE),0)+_xlfn.IFNA(VLOOKUP(C51,$AM$4:$AP$30,4,FALSE),0)+_xlfn.IFNA(VLOOKUP(C51,$AS$4:$AV$30,4,FALSE),0)+_xlfn.IFNA(VLOOKUP(C51,$AY$4:$BB$30,4,FALSE),0)+_xlfn.IFNA(VLOOKUP(C51,$BE$4:$BH$29,4,FALSE),0)+_xlfn.IFNA(VLOOKUP(C51,$BK$4:$BN$31,4,FALSE),0)+_xlfn.IFNA(VLOOKUP(C51,$BQ$4:$BT$32,4,FALSE),0)+_xlfn.IFNA(VLOOKUP(C51,$BW$4:$BZ$32,4,FALSE),0)+_xlfn.IFNA(VLOOKUP(C51,$CC$4:$CF$32,4,FALSE),0)+_xlfn.IFNA(VLOOKUP(C51,$CI$4:$CL$32,4,FALSE),0)+_xlfn.IFNA(VLOOKUP(C51,$CO$4:$CR$32,4,FALSE),0)+_xlfn.IFNA(VLOOKUP(C51,$CU$4:$CX$32,4,FALSE),0)+_xlfn.IFNA(VLOOKUP(C51,$DA$4:$DD$32,4,FALSE),0)+_xlfn.IFNA(VLOOKUP(C51,$DG$4:$DJ$32,4,FALSE),0)+_xlfn.IFNA(VLOOKUP(C51,$DM$4:$DP$32,4,FALSE),0)+_xlfn.IFNA(VLOOKUP(C51,$DS$4:$DV$32,4,FALSE),0) -> 578 | F51: Dylan Groenewegen | G51: 207 | N51: 15 | O51: Laurens De Plus | P51: 33 | R51: Casper | S51: 2 | T51: 220
B52: 17 | C52: Derek Gee | D52: =_xlfn.IFNA(VLOOKUP(C52,$I$4:$L$30,4,FALSE),0)+_xlfn.IFNA(VLOOKUP(C52,$C$4:$F$28,4,FALSE),0)+_xlfn.IFNA(VLOOKUP(C52,$U$4:$X$30,4,FALSE),0)+_xlfn.IFNA(VLOOKUP(C52,$O$4:$R$30,4,FALSE),0)+_xlfn.IFNA(VLOOKUP(C52,$AA$4:$AD$30,4,FALSE),0)+_xlfn.IFNA(VLOOKUP(C52,$AG$4:$AJ$30,4,FALSE),0)+_xlfn.IFNA(VLOOKUP(C52,$AM$4:$AP$30,4,FALSE),0)+_xlfn.IFNA(VLOOKUP(C52,$AS$4:$AV$30,4,FALSE),0)+_xlfn.IFNA(VLOOKUP(C52,$AY$4:$BB$30,4,FALSE),0)+_xlfn.IFNA(VLOOKUP(C52,$BE$4:$BH$29,4,FALSE),0)+_xlfn.IFNA(VLOOKUP(C52,$BK$4:$BN$31,4,FALSE),0)+_xlfn.IFNA(VLOOKUP(C52,$BQ$4:$BT$32,4,FALSE),0)+_xlfn.IFNA(VLOOKUP(C52,$BW$4:$BZ$32,4,FALSE),0)+_xlfn.IFNA(VLOOKUP(C52,$CC$4:$CF$32,4,FALSE),0)+_xlfn.IFNA(VLOOKUP(C52,$CI$4:$CL$32,4,FALSE),0)+_xlfn.IFNA(VLOOKUP(C52,$CO$4:$CR$32,4,FALSE),0)+_xlfn.IFNA(VLOOKUP(C52,$CU$4:$CX$32,4,FALSE),0)+_xlfn.IFNA(VLOOKUP(C52,$DA$4:$DD$32,4,FALSE),0)+_xlfn.IFNA(VLOOKUP(C52,$DG$4:$DJ$32,4,FALSE),0)+_xlfn.IFNA(VLOOKUP(C52,$DM$4:$DP$32,4,FALSE),0)+_xlfn.IFNA(VLOOKUP(C52,$DS$4:$DV$32,4,FALSE),0) -> 209 | F52: Mikel Landa | G52: 205 | N52: 16 | O52: Steff Cras | P52: 30
B53: 18 | C53: Aleksandr Vlasov | D53: =_xlfn.IFNA(VLOOKUP(C53,$I$4:$L$30,4,FALSE),0)+_xlfn.IFNA(VLOOKUP(C53,$C$4:$F$28,4,FALSE),0)+_xlfn.IFNA(VLOOKUP(C53,$U$4:$X$30,4,FALSE),0)+_xlfn.IFNA(VLOOKUP(C53,$O$4:$R$30,4,FALSE),0)+_xlfn.IFNA(VLOOKUP(C53,$AA$4:$AD$30,4,FALSE),0)+_xlfn.IFNA(VLOOKUP(C53,$AG$4:$AJ$30,4,FALSE),0)+_xlfn.IFNA(VLOOKUP(C53,$AM$4:$AP$30,4,FALSE),0)+_xlfn.IFNA(VLOOKUP(C53,$AS$4:$AV$30,4,FALSE),0)+_xlfn.IFNA(VLOOKUP(C53,$AY$4:$BB$30,4,FALSE),0)+_xlfn.IFNA(VLOOKUP(C53,$BE$4:$BH$29,4,FALSE),0)+_xlfn.IFNA(VLOOKUP(C53,$BK$4:$BN$31,4,FALSE),0)+_xlfn.IFNA(VLOOKUP(C53,$BQ$4:$BT$32,4,FALSE),0)+_xlfn.IFNA(VLOOKUP(C53,$BW$4:$BZ$32,4,FALSE),0)+_xlfn.IFNA(VLOOKUP(C53,$CC$4:$CF$32,4,FALSE),0)+_xlfn.IFNA(VLOOKUP(C53,$CI$4:$CL$32,4,FALSE),0)+_xlfn.IFNA(VLOOKUP(C53,$CO$4:$CR$32,4,FALSE),0)+_xlfn.IFNA(VLOOKUP(C53,$CU$4:$CX$32,4,FALSE),0)+_xlfn.IFNA(VLOOKUP(C53,$DA$4:$DD$32,4,FALSE),0)+_xlfn.IFNA(VLOOKUP(C53,$DG$4:$DJ$32,4,FALSE),0)+_xlfn.IFNA(VLOOKUP(C53,$DM$4:$DP$32,4,FALSE),0)+_xlfn.IFNA(VLOOKUP(C53,$DS$4:$DV$32,4,FALSE),0) -> 36 | F53: Simon Yates | G53: 203 | N53: 17 | O53: Richard Carapaz | P53: 27 | R53: Jongerentrui
B54: 19 | C54: Toms Skujins | D54: =_xlfn.IFNA(VLOOKUP(C54,$I$4:$L$30,4,FALSE),0)+_xlfn.IFNA(VLOOKUP(C54,$C$4:$F$28,4,FALSE),0)+_xlfn.IFNA(VLOOKUP(C54,$U$4:$X$30,4,FALSE),0)+_xlfn.IFNA(VLOOKUP(C54,$O$4:$R$30,4,FALSE),0)+_xlfn.IFNA(VLOOKUP(C54,$AA$4:$AD$30,4,FALSE),0)+_xlfn.IFNA(VLOOKUP(C54,$AG$4:$AJ$30,4,FALSE),0)+_xlfn.IFNA(VLOOKUP(C54,$AM$4:$AP$30,4,FALSE),0)+_xlfn.IFNA(VLOOKUP(C54,$AS$4:$AV$30,4,FALSE),0)+_xlfn.IFNA(VLOOKUP(C54,$AY$4:$BB$30,4,FALSE),0)+_xlfn.IFNA(VLOOKUP(C54,$BE$4:$BH$29,4,FALSE),0)+_xlfn.IFNA(VLOOKUP(C54,$BK$4:$BN$31,4,FALSE),0)+_xlfn.IFNA(VLOOKUP(C54,$BQ$4:$BT$32,4,FALSE),0)+_xlfn.IFNA(VLOOKUP(C54,$BW$4:$BZ$32,4,FALSE),0)+_xlfn.IFNA(VLOOKUP(C54,$CC$4:$CF$32,4,FALSE),0)+_xlfn.IFNA(VLOOKUP(C54,$CI$4:$CL$32,4,FALSE),0)+_xlfn.IFNA(VLOOKUP(C54,$CO$4:$CR$32,4,FALSE),0)+_xlfn.IFNA(VLOOKUP(C54,$CU$4:$CX$32,4,FALSE),0)+_xlfn.IFNA(VLOOKUP(C54,$DA$4:$DD$32,4,FALSE),0)+_xlfn.IFNA(VLOOKUP(C54,$DG$4:$DJ$32,4,FALSE),0)+_xlfn.IFNA(VLOOKUP(C54,$DM$4:$DP$32,4,FALSE),0)+_xlfn.IFNA(VLOOKUP(C54,$DS$4:$DV$32,4,FALSE),0) -> 82 | F54: Carlos Rodriguez | G54: 191 | N54: 18 | O54: Jai Hindley | P54: 24 | R54: Jonas | S54: 1 | T54: 15
B55: 20 | C55: Geraint Thomas | D55: =_xlfn.IFNA(VLOOKUP(C55,$I$4:$L$30,4,FALSE),0)+_xlfn.IFNA(VLOOKUP(C55,$C$4:$F$28,4,FALSE),0)+_xlfn.IFNA(VLOOKUP(C55,$U$4:$X$30,4,FALSE),0)+_xlfn.IFNA(VLOOKUP(C55,$O$4:$R$30,4,FALSE),0)+_xlfn.IFNA(VLOOKUP(C55,$AA$4:$AD$30,4,FALSE),0)+_xlfn.IFNA(VLOOKUP(C55,$AG$4:$AJ$30,4,FALSE),0)+_xlfn.IFNA(VLOOKUP(C55,$AM$4:$AP$30,4,FALSE),0)+_xlfn.IFNA(VLOOKUP(C55,$AS$4:$AV$30,4,FALSE),0)+_xlfn.IFNA(VLOOKUP(C55,$AY$4:$BB$30,4,FALSE),0)+_xlfn.IFNA(VLOOKUP(C55,$BE$4:$BH$29,4,FALSE),0)+_xlfn.IFNA(VLOOKUP(C55,$BK$4:$BN$31,4,FALSE),0)+_xlfn.IFNA(VLOOKUP(C55,$BQ$4:$BT$32,4,FALSE),0)+_xlfn.IFNA(VLOOKUP(C55,$BW$4:$BZ$32,4,FALSE),0)+_xlfn.IFNA(VLOOKUP(C55,$CC$4:$CF$32,4,FALSE),0)+_xlfn.IFNA(VLOOKUP(C55,$CI$4:$CL$32,4,FALSE),0)+_xlfn.IFNA(VLOOKUP(C55,$CO$4:$CR$32,4,FALSE),0)+_xlfn.IFNA(VLOOKUP(C55,$CU$4:$CX$32,4,FALSE),0)+_xlfn.IFNA(VLOOKUP(C55,$DA$4:$DD$32,4,FALSE),0)+_xlfn.IFNA(VLOOKUP(C55,$DG$4:$DJ$32,4,FALSE),0)+_xlfn.IFNA(VLOOKUP(C55,$DM$4:$DP$32,4,FALSE),0)+_xlfn.IFNA(VLOOKUP(C55,$DS$4:$DV$32,4,FALSE),0) -> 17 | F55: Anthony Turgis | G55: 187 | N55: 19 | O55: Enric Mas | P55: 21 | R55: Casper | S55: 3 | T55: 92
...

Sheet Grafieken

Sheet Blad1
A3: Scenario 1
A4: Dezelfde renner heeft elke rit 1 van de 4 truien én wint het eindklassement van zijn trui
B6: Ritten | C6: Algemeen | D6: Sprint | E6: Berg | F6: Jongeren | I6: Ritten | J6: Algemeen | K6: Sprint | L6: Berg | M6: Jongeren | P6: Ritten | Q6: Algemeen | R6: Sprint | S6: Berg | T6: Jongeren
B7: Rit 1 | C7: 20 | D7: 10 | E7: 10 | F7: 5 | I7: Rit 1 | J7: 10 | K7: 10 | L7: 10 | M7: 10 | P7: Rit 1 | Q7: 12 | R7: 10 | S7: 10 | T7: 10
B8: Rit 2 | C8: 20 | D8: 10 | E8: 10 | F8: 5 | I8: Rit 2 | J8: 10 | K8: 10 | L8: 10 | M8: 10 | P8: Rit 2 | Q8: 12 | R8: 10 | S8: 10 | T8: 10
B9: Rit 3 | C9: 20 | D9: 10 | E9: 10 | F9: 5 | I9: Rit 3 | J9: 10 | K9: 10 | L9: 10 | M9: 10 | P9: Rit 3 | Q9: 12 | R9: 10 | S9: 10 | T9: 10
B10: Rit 4 | C10: 20 | D10: 10 | E10: 10 | F10: 5 | I10: Rit 4 | J10: 10 | K10: 10 | L10: 10 | M10: 10 | P10: Rit 4 | Q10: 12 | R10: 10 | S10: 10 | T10: 10
B11: Rit 5 | C11: 20 | D11: 10 | E11: 10 | F11: 5 | I11: Rit 5 | J11: 10 | K11: 10 | L11: 10 | M11: 10 | P11: Rit 5 | Q11: 12 | R11: 10 | S11: 10 | T11: 10
B12: Rit 6 | C12: 20 | D12: 10 | E12: 10 | F12: 5 | I12: Rit 6 | J12: 10 | K12: 10 | L12: 10 | M12: 10 | P12: Rit 6 | Q12: 12 | R12: 10 | S12: 10 | T12: 10
